Workbook

Sheet Waybill
A1: 批次号 | B1: 运单号 | C1: 停靠点顺序 | D1: 门店名称 | E1: 经度 | F1: 纬度 | G1: 详细地址 | H1: 门店联系电话 | I1: 货物信息 | J1: 配送日期 | K1: 司机姓名 | L1: 司机电话 | M1: 车牌号 | N1: 供应商名称 | O1: 仓库名称
A2: =数据输入表!B1 -> LC20260421000980 | B2: FS-WB-SAMPLE-01 | C2: =IF(D2<>"",ROW()-1,"") | E2: =IF(D2="","",IFERROR(_xlfn.XLOOKUP(D2,客户信息底表!B:B,客户信息底表!Q:Q,,0),IFERROR(_xlfn.XLOOKUP(D2,客户信息底表!BB:BB,客户信息底表!Q:Q,,0),IFERROR(_xlfn.XLOOKUP(D2,客户信息底表!BC:BC,客户信息底表!Q:Q,,0),IFERROR(_xlfn.XLOOKUP(D2,客户信息底表!BD:BD,客户信息底表!Q:Q,,0),"底表未登记"))))) | F2: =IF(D2="","",IFERROR(_xlfn.XLOOKUP(D2,客户信息底表!B:B,客户信息底表!R:R,,0),IFERROR(_xlfn.XLOOKUP(D2,客户信息底表!BB:BB,客户信息底表!R:R,,0),IFERROR(_xlfn.XLOOKUP(D2,客户信息底表!BC:BC,客户信息底表!R:R,,0),IFERROR(_xlfn.XLOOKUP(D2,客户信息底表!BD:BD,客户信息底表!R:R,,0),"底表未登记"))))) | G2: =IF(D2="","",IFERROR(_xlfn.XLOOKUP(D2,客户信息底表!B:B,客户信息底表!L:L,,0),IFERROR(_xlfn.XLOOKUP(D2,客户信息底表!BB:BB,客户信息底表!L:L,,0),IFERROR(_xlfn.XLOOKUP(D2,客户信息底表!BC:BC,客户信息底表!L:L,,0),IFERROR(_xlfn.XLOOKUP(D2,客户信息底表!BD:BD,客户信息底表!L:L,,0),"底表未登记"))))) | H2: =IF(D2="","",IFERROR(_xlfn.XLOOKUP(D2,客户信息底表!B:B,客户信息底表!G:G,,0),IFERROR(_xlfn.XLOOKUP(D2,客户信息底表!BB:BB,客户信息底表!G:G,,0),IFERROR(_xlfn.XLOOKUP(D2,客户信息底表!BC:BC,客户信息底表!G:G,,0),IFERROR(_xlfn.XLOOKUP(D2,客户信息底表!BD:BD,客户信息底表!G:G,,0),"底表未登记"))))) | I2: =IF(D2="","","整："&数据输入表!J5&"，散："&数据输入表!K5&"；重量kg："&数据输入表!L5&"，体积："&数据输入表!M5) | J2: 46136 | O2: WH
A3: =IF(D3<>"",$A$2,"") -> LC20260421000980 | B3: FS-WB-SAMPLE-02 | C3: =IF(D3<>"",ROW()-1,"") -> 2 | D3: =IF(数据输入表!H6="","",数据输入表!H6) -> 鲸选超市（广州板桥店) | E3: =IF(D3="","",IFERROR(_xlfn.XLOOKUP(D3,客户信息底表!B:B,客户信息底表!Q:Q,,0),IFERROR(_xlfn.XLOOKUP(D3,客户信息底表!BB:BB,客户信息底表!Q:Q,,0),IFERROR(_xlfn.XLOOKUP(D3,客户信息底表!BC:BC,客户信息底表!Q:Q,,0),IFERROR(_xlfn.XLOOKUP(D3,客户信息底表!BD:BD,客户信息底表!Q:Q,,0),"底表未登记"))))) -> 113.38793 | F3: =IF(D3="","",IFERROR(_xlfn.XLOOKUP(D3,客户信息底表!B:B,客户信息底表!R:R,,0),IFERROR(_xlfn.XLOOKUP(D3,客户信息底表!BB:BB,客户信息底表!R:R,,0),IFERROR(_xlfn.XLOOKUP(D3,客户信息底表!BC:BC,客户信息底表!R:R,,0),IFERROR(_xlfn.XLOOKUP(D3,客户信息底表!BD:BD,客户信息底表!R:R,,0),"底表未登记"))))) -> 23.009784 | G3: =IF(D3="","",IFERROR(_xlfn.XLOOKUP(D3,客户信息底表!B:B,客户信息底表!L:L,,0),IFERROR(_xlfn.XLOOKUP(D3,客户信息底表!BB:BB,客户信息底表!L:L,,0),IFERROR(_xlfn.XLOOKUP(D3,客户信息底表!BC:BC,客户信息底表!L:L,,0),IFERROR(_xlfn.XLOOKUP(D3,客户信息底表!BD:BD,客户信息底表!L:L,,0),"底表未登记"))))) -> 南村镇兴南大道902号板桥商务大厦3楼315号 | H3: =IF(D3="","",IFERROR(_xlfn.XLOOKUP(D3,客户信息底表!B:B,客户信息底表!G:G,,0),IFERROR(_xlfn.XLOOKUP(D3,客户信息底表!BB:BB,客户信息底表!G:G,,0),IFERROR(_xlfn.XLOOKUP(D3,客户信息底表!BC:BC,客户信息底表!G:G,,0),IFERROR(_xlfn.XLOOKUP(D3,客户信息底表!BD:BD,客户信息底表!G:G,,0),"底表未登记"))))) -> 13533764129 | I3: =IF(D3="","","整："&数据输入表!J6&"，散："&数据输入表!K6&"；重量kg："&数据输入表!L6&"，体积："&数据输入表!M6) -> 整：11，散：190；重量kg：190，体积：0.03 | J3: 46136 | O3: WH
A4: =IF(D4<>"",$A$2,"") -> LC20260421000980 | B4: FS-WB-SAMPLE-03 | C4: =IF(D4<>"",ROW()-1,"") -> 3 | D4: =IF(数据输入表!H7="","",数据输入表!H7) -> 鲸选超市（广州番禺店) | E4: =IF(D4="","",IFERROR(_xlfn.XLOOKUP(D4,客户信息底表!B:B,客户信息底表!Q:Q,,0),IFERROR(_xlfn.XLOOKUP(D4,客户信息底表!BB:BB,客户信息底表!Q:Q,,0),IFERROR(_xlfn.XLOOKUP(D4,客户信息底表!BC:BC,客户信息底表!Q:Q,,0),IFERROR(_xlfn.XLOOKUP(D4,客户信息底表!BD:BD,客户信息底表!Q:Q,,0),"底表未登记"))))) -> 113.35109 | F4: =IF(D4="","",IFERROR(_xlfn.XLOOKUP(D4,客户信息底表!B:B,客户信息底表!R:R,,0),IFERROR(_xlfn.XLOOKUP(D4,客户信息底表!BB:BB,客户信息底表!R:R,,0),IFERROR(_xlfn.XLOOKUP(D4,客户信息底表!BC:BC,客户信息底表!R:R,,0),IFERROR(_xlfn.XLOOKUP(D4,客户信息底表!BD:BD,客户信息底表!R:R,,0),"底表未登记"))))) -> 23.001303 | G4: =IF(D4="","",IFERROR(_xlfn.XLOOKUP(D4,客户信息底表!B:B,客户信息底表!L:L,,0),IFERROR(_xlfn.XLOOKUP(D4,客户信息底表!BB:BB,客户信息底表!L:L,,0),IFERROR(_xlfn.XLOOKUP(D4,客户信息底表!BC:BC,客户信息底表!L:L,,0),IFERROR(_xlfn.XLOOKUP(D4,客户信息底表!BD:BD,客户信息底表!L:L,,0),"底表未登记"))))) -> 南村镇敏捷上城国际【2期2座112店铺2楼京东便利店仓库】 | H4: =IF(D4="","",IFERROR(_xlfn.XLOOKUP(D4,客户信息底表!B:B,客户信息底表!G:G,,0),IFERROR(_xlfn.XLOOKUP(D4,客户信息底表!BB:BB,客户信息底表!G:G,,0),IFERROR(_xlfn.XLOOKUP(D4,客户信息底表!BC:BC,客户信息底表!G:G,,0),IFERROR(_xlfn.XLOOKUP(D4,客户信息底表!BD:BD,客户信息底表!G:G,,0),"底表未登记"))))) -> 13533764129 | I4: =IF(D4="","","整："&数据输入表!J7&"，散："&数据输入表!K7&"；重量kg："&数据输入表!L7&"，体积："&数据输入表!M7) -> 整：4，散：110；重量kg：110，体积：0.01 | J4: 46136 | O4: WH
A5: =IF(D5<>"",$A$2,"") -> LC20260421000980 | B5: FS-WB-SAMPLE-04 | C5: =IF(D5<>"",ROW()-1,"") -> 4 | D5: =IF(数据输入表!H8="","",数据输入表!H8) -> 时光里便利超市（广州番禺万博店） | E5: =IF(D5="","",IFERROR(_xlfn.XLOOKUP(D5,客户信息底表!B:B,客户信息底表!Q:Q,,0),IFERROR(_xlfn.XLOOKUP(D5,客户信息底表!BB:BB,客户信息底表!Q:Q,,0),IFERROR(_xlfn.XLOOKUP(D5,客户信息底表!BC:BC,客户信息底表!Q:Q,,0),IFERROR(_xlfn.XLOOKUP(D5,客户信息底表!BD:BD,客户信息底表!Q:Q,,0),"底表未登记"))))) -> 113.34426 | F5: =IF(D5="","",IFERROR(_xlfn.XLOOKUP(D5,客户信息底表!B:B,客户信息底表!R:R,,0),IFERROR(_xlfn.XLOOKUP(D5,客户信息底表!BB:BB,客户信息底表!R:R,,0),IFERROR(_xlfn.XLOOKUP(D5,客户信息底表!BC:BC,客户信息底表!R:R,,0),IFERROR(_xlfn.XLOOKUP(D5,客户信息底表!BD:BD,客户信息底表!R:R,,0),"底表未登记"))))) -> 23.013173 | G5: =IF(D5="","",IFERROR(_xlfn.XLOOKUP(D5,客户信息底表!B:B,客户信息底表!L:L,,0),IFERROR(_xlfn.XLOOKUP(D5,客户信息底表!BB:BB,客户信息底表!L:L,,0),IFERROR(_xlfn.XLOOKUP(D5,客户信息底表!BC:BC,客户信息底表!L:L,,0),IFERROR(_xlfn.XLOOKUP(D5,客户信息底表!BD:BD,客户信息底表!L:L,,0),"底表未登记"))))) -> 南村镇登云大路2号之六105房 | H5: =IF(D5="","",IFERROR(_xlfn.XLOOKUP(D5,客户信息底表!B:B,客户信息底表!G:G,,0),IFERROR(_xlfn.XLOOKUP(D5,客户信息底表!BB:BB,客户信息底表!G:G,,0),IFERROR(_xlfn.XLOOKUP(D5,客户信息底表!BC:BC,客户信息底表!G:G,,0),IFERROR(_xlfn.XLOOKUP(D5,客户信息底表!BD:BD,客户信息底表!G:G,,0),"底表未登记"))))) -> 13318758760 | I5: =IF(D5="","","整："&数据输入表!J8&"，散："&数据输入表!K8&"；重量kg："&数据输入表!L8&"，体积："&数据输入表!M8) -> 整：6，散：107；重量kg：107，体积：0.05 | J5: 46136 | O5: WH
A6: =IF(D6<>"",$A$2,"") -> LC20260421000980 | B6: FS-WB-SAMPLE-05 | C6: =IF(D6<>"",ROW()-1,"") -> 5 | D6: =IF(数据输入表!H9="","",数据输入表!H9) -> 熊猫很忙（大石店-广东广州） | E6: =IF(D6="","",IFERROR(_xlfn.XLOOKUP(D6,客户信息底表!B:B,客户信息底表!Q:Q,,0),IFERROR(_xlfn.XLOOKUP(D6,客户信息底表!BB:BB,客户信息底表!Q:Q,,0),IFERROR(_xlfn.XLOOKUP(D6,客户信息底表!BC:BC,客户信息底表!Q:Q,,0),IFERROR(_xlfn.XLOOKUP(D6,客户信息底表!BD:BD,客户信息底表!Q:Q,,0),"底表未登记"))))) -> 113.32446 | F6: =IF(D6="","",IFERROR(_xlfn.XLOOKUP(D6,客户信息底表!B:B,客户信息底表!R:R,,0),IFERROR(_xlfn.XLOOKUP(D6,客户信息底表!BB:BB,客户信息底表!R:R,,0),IFERROR(_xlfn.XLOOKUP(D6,客户信息底表!BC:BC,客户信息底表!R:R,,0),IFERROR(_xlfn.XLOOKUP(D6,客户信息底表!BD:BD,客户信息底表!R:R,,0),"底表未登记"))))) -> 23.023298 | G6: =IF(D6="","",IFERROR(_xlfn.XLOOKUP(D6,客户信息底表!B:B,客户信息底表!L:L,,0),IFERROR(_xlfn.XLOOKUP(D6,客户信息底表!BB:BB,客户信息底表!L:L,,0),IFERROR(_xlfn.XLOOKUP(D6,客户信息底表!BC:BC,客户信息底表!L:L,,0),IFERROR(_xlfn.XLOOKUP(D6,客户信息底表!BD:BD,客户信息底表!L:L,,0),"底表未登记"))))) -> 大石街大山村富山路四街1号胜文工业园2栋1楼103室 | H6: =IF(D6="","",IFERROR(_xlfn.XLOOKUP(D6,客户信息底表!B:B,客户信息底表!G:G,,0),IFERROR(_xlfn.XLOOKUP(D6,客户信息底表!BB:BB,客户信息底表!G:G,,0),IFERROR(_xlfn.XLOOKUP(D6,客户信息底表!BC:BC,客户信息底表!G:G,,0),IFERROR(_xlfn.XLOOKUP(D6,客户信息底表!BD:BD,客户信息底表!G:G,,0),"底表未登记"))))) -> 15018430593 | I6: =IF(D6="","","整："&数据输入表!J9&"，散："&数据输入表!K9&"；重量kg："&数据输入表!L9&"，体积："&数据输入表!M9) -> 整：2，散：125；重量kg：125，体积：0.01 | J6: 46136 | O6: WH
A7: =IF(D7<>"",$A$2,"") -> LC20260421000980 | B7: FS-WB-SAMPLE-06 | C7: =IF(D7<>"",ROW()-1,"") -> 6 | D7: =IF(数据输入表!H10="","",数据输入表!H10) -> 值小团（广州大石店） | E7: =IF(D7="","",IFERROR(_xlfn.XLOOKUP(D7,客户信息底表!B:B,客户信息底表!Q:Q,,0),IFERROR(_xlfn.XLOOKUP(D7,客户信息底表!BB:BB,客户信息底表!Q:Q,,0),IFERROR(_xlfn.XLOOKUP(D7,客户信息底表!BC:BC,客户信息底表!Q:Q,,0),IFERROR(_xlfn.XLOOKUP(D7,客户信息底表!BD:BD,客户信息底表!Q:Q,,0),"底表未登记"))))) -> 113.3196 | F7: =IF(D7="","",IFERROR(_xlfn.XLOOKUP(D7,客户信息底表!B:B,客户信息底表!R:R,,0),IFERROR(_xlfn.XLOOKUP(D7,客户信息底表!BB:BB,客户信息底表!R:R,,0),IFERROR(_xlfn.XLOOKUP(D7,客户信息底表!BC:BC,客户信息底表!R:R,,0),IFERROR(_xlfn.XLOOKUP(D7,客户信息底表!BD:BD,客户信息底表!R:R,,0),"底表未登记"))))) -> 23.026733 | G7: =IF(D7="","",IFERROR(_xlfn.XLOOKUP(D7,客户信息底表!B:B,客户信息底表!L:L,,0),IFERROR(_xlfn.XLOOKUP(D7,客户信息底表!BB:BB,客户信息底表!L:L,,0),IFERROR(_xlfn.XLOOKUP(D7,客户信息底表!BC:BC,客户信息底表!L:L,,0),IFERROR(_xlfn.XLOOKUP(D7,客户信息底表!BD:BD,客户信息底表!L:L,,0),"底表未登记"))))) -> 大石街道大石镇朝阳东路170号201房值小团超市（原玲丰服饰） | H7: =IF(D7="","",IFERROR(_xlfn.XLOOKUP(D7,客户信息底表!B:B,客户信息底表!G:G,,0),IFERROR(_xlfn.XLOOKUP(D7,客户信息底表!BB:BB,客户信息底表!G:G,,0),IFERROR(_xlfn.XLOOKUP(D7,客户信息底表!BC:BC,客户信息底表!G:G,,0),IFERROR(_xlfn.XLOOKUP(D7,客户信息底表!BD:BD,客户信息底表!G:G,,0),"底表未登记"))))) -> 19068527315 | I7: =IF(D7="","","整："&数据输入表!J10&"，散："&数据输入表!K10&"；重量kg："&数据输入表!L10&"，体积："&数据输入表!M10) -> 整：3，散：60；重量kg：60，体积：0.01 | J7: 46136 | O7: WH
A8: =IF(D8<>"",$A$2,"") -> LC20260421000980 | B8: FS-WB-SAMPLE-07 | C8: =IF(D8<>"",ROW()-1,"") -> 7 | D8: =IF(数据输入表!H11="","",数据输入表!H11) -> 鲸选超市（广州大石店) | E8: =IF(D8="","",IFERROR(_xlfn.XLOOKUP(D8,客户信息底表!B:B,客户信息底表!Q:Q,,0),IFERROR(_xlfn.XLOOKUP(D8,客户信息底表!BB:BB,客户信息底表!Q:Q,,0),IFERROR(_xlfn.XLOOKUP(D8,客户信息底表!BC:BC,客户信息底表!Q:Q,,0),IFERROR(_xlfn.XLOOKUP(D8,客户信息底表!BD:BD,客户信息底表!Q:Q,,0),"底表未登记"))))) -> 113.31744 | F8: =IF(D8="","",IFERROR(_xlfn.XLOOKUP(D8,客户信息底表!B:B,客户信息底表!R:R,,0),IFERROR(_xlfn.XLOOKUP(D8,客户信息底表!BB:BB,客户信息底表!R:R,,0),IFERROR(_xlfn.XLOOKUP(D8,客户信息底表!BC:BC,客户信息底表!R:R,,0),IFERROR(_xlfn.XLOOKUP(D8,客户信息底表!BD:BD,客户信息底表!R:R,,0),"底表未登记"))))) -> 23.022374 | G8: =IF(D8="","",IFERROR(_xlfn.XLOOKUP(D8,客户信息底表!B:B,客户信息底表!L:L,,0),IFERROR(_xlfn.XLOOKUP(D8,客户信息底表!BB:BB,客户信息底表!L:L,,0),IFERROR(_xlfn.XLOOKUP(D8,客户信息底表!BC:BC,客户信息底表!L:L,,0),IFERROR(_xlfn.XLOOKUP(D8,客户信息底表!BD:BD,客户信息底表!L:L,,0),"底表未登记"))))) -> 大石街道大涌路157号大石伟讯电子数码城4楼421铺 | H8: =IF(D8="","",IFERROR(_xlfn.XLOOKUP(D8,客户信息底表!B:B,客户信息底表!G:G,,0),IFERROR(_xlfn.XLOOKUP(D8,客户信息底表!BB:BB,客户信息底表!G:G,,0),IFERROR(_xlfn.XLOOKUP(D8,客户信息底表!BC:BC,客户信息底表!G:G,,0),IFERROR(_xlfn.XLOOKUP(D8,客户信息底表!BD:BD,客户信息底表!G:G,,0),"底表未登记"))))) -> 13533764129 | I8: =IF(D8="","","整："&数据输入表!J11&"，散："&数据输入表!K11&"；重量kg："&数据输入表!L11&"，体积："&数据输入表!M11) -> 整：9，散：207；重量kg：207，体积：0.03 | J8: 46136 | O8: WH
A9: =IF(D9<>"",$A$2,"") -> LC20260421000980 | B9: FS-WB-SAMPLE-08 | C9: =IF(D9<>"",ROW()-1,"") -> 8 | D9: =IF(数据输入表!H12="","",数据输入表!H12) -> 熊猫很忙（鹤洞店-广东广州）（直营） | E9: =IF(D9="","",IFERROR(_xlfn.XLOOKUP(D9,客户信息底表!B:B,客户信息底表!Q:Q,,0),IFERROR(_xlfn.XLOOKUP(D9,客户信息底表!BB:BB,客户信息底表!Q:Q,,0),IFERROR(_xlfn.XLOOKUP(D9,客户信息底表!BC:BC,客户信息底表!Q:Q,,0),IFERROR(_xlfn.XLOOKUP(D9,客户信息底表!BD:BD,客户信息底表!Q:Q,,0),"底表未登记"))))) -> 113.236 | F9: =IF(D9="","",IFERROR(_xlfn.XLOOKUP(D9,客户信息底表!B:B,客户信息底表!R:R,,0),IFERROR(_xlfn.XLOOKUP(D9,客户信息底表!BB:BB,客户信息底表!R:R,,0),IFERROR(_xlfn.XLOOKUP(D9,客户信息底表!BC:BC,客户信息底表!R:R,,0),IFERROR(_xlfn.XLOOKUP(D9,客户信息底表!BD:BD,客户信息底表!R:R,,0),"底表未登记"))))) -> 23.068962 | G9: =IF(D9="","",IFERROR(_xlfn.XLOOKUP(D9,客户信息底表!B:B,客户信息底表!L:L,,0),IFERROR(_xlfn.XLOOKUP(D9,客户信息底表!BB:BB,客户信息底表!L:L,,0),IFERROR(_xlfn.XLOOKUP(D9,客户信息底表!BC:BC,客户信息底表!L:L,,0),IFERROR(_xlfn.XLOOKUP(D9,客户信息底表!BD:BD,客户信息底表!L:L,,0),"底表未登记"))))) -> 鹤洞路346号218室2楼送货上门6688不放驿站 | H9: =IF(D9="","",IFERROR(_xlfn.XLOOKUP(D9,客户信息底表!B:B,客户信息底表!G:G,,0),IFERROR(_xlfn.XLOOKUP(D9,客户信息底表!BB:BB,客户信息底表!G:G,,0),IFERROR(_xlfn.XLOOKUP(D9,客户信息底表!BC:BC,客户信息底表!G:G,,0),IFERROR(_xlfn.XLOOKUP(D9,客户信息底表!BD:BD,客户信息底表!G:G,,0),"底表未登记"))))) -> 17722262342 | I9: =IF(D9="","","整："&数据输入表!J12&"，散："&数据输入表!K12&"；重量kg："&数据输入表!L12&"，体积："&数据输入表!M12) -> 整：6，散：102；重量kg：102，体积：0.01 | J9: 46136 | O9: WH
A10: =IF(D10<>"",$A$2,"") -> LC20260421000980 | B10: FS-WB-SAMPLE-09 | C10: =IF(D10<>"",ROW()-1,"") -> 9 | D10: =IF(数据输入表!H13="","",数据输入表!H13) -> 值小团（广州芳村店） | E10: =IF(D10="","",IFERROR(_xlfn.XLOOKUP(D10,客户信息底表!B:B,客户信息底表!Q:Q,,0),IFERROR(_xlfn.XLOOKUP(D10,客户信息底表!BB:BB,客户信息底表!Q:Q,,0),IFERROR(_xlfn.XLOOKUP(D10,客户信息底表!BC:BC,客户信息底表!Q:Q,,0),IFERROR(_xlfn.XLOOKUP(D10,客户信息底表!BD:BD,客户信息底表!Q:Q,,0),"底表未登记"))))) -> 113.23805 | F10: =IF(D10="","",IFERROR(_xlfn.XLOOKUP(D10,客户信息底表!B:B,客户信息底表!R:R,,0),IFERROR(_xlfn.XLOOKUP(D10,客户信息底表!BB:BB,客户信息底表!R:R,,0),IFERROR(_xlfn.XLOOKUP(D10,客户信息底表!BC:BC,客户信息底表!R:R,,0),IFERROR(_xlfn.XLOOKUP(D10,客户信息底表!BD:BD,客户信息底表!R:R,,0),"底表未登记"))))) -> 23.076417 | G10: =IF(D10="","",IFERROR(_xlfn.XLOOKUP(D10,客户信息底表!B:B,客户信息底表!L:L,,0),IFERROR(_xlfn.XLOOKUP(D10,客户信息底表!BB:BB,客户信息底表!L:L,,0),IFERROR(_xlfn.XLOOKUP(D10,客户信息底表!BC:BC,客户信息底表!L:L,,0),IFERROR(_xlfn.XLOOKUP(D10,客户信息底表!BD:BD,客户信息底表!L:L,,0),"底表未登记"))))) -> 坑口大街 138 号红岗工业区1 号首层 101、102 室 | H10: =IF(D10="","",IFERROR(_xlfn.XLOOKUP(D10,客户信息底表!B:B,客户信息底表!G:G,,0),IFERROR(_xlfn.XLOOKUP(D10,客户信息底表!BB:BB,客户信息底表!G:G,,0),IFERROR(_xlfn.XLOOKUP(D10,客户信息底表!BC:BC,客户信息底表!G:G,,0),IFERROR(_xlfn.XLOOKUP(D10,客户信息底表!BD:BD,客户信息底表!G:G,,0),"底表未登记"))))) -> 17575037885 | I10: =IF(D10="","","整："&数据输入表!J13&"，散："&数据输入表!K13&"；重量kg："&数据输入表!L13&"，体积："&数据输入表!M13) -> 整：7，散：114；重量kg：114，体积：0.03 | J10: 46136 | O10: WH
A11: =IF(D11<>"",$A$2,"") -> LC20260421000980 | B11: FS-WB-SAMPLE-10 | C11: =IF(D11<>"",ROW()-1,"") -> 10 | D11: =IF(数据输入表!H14="","",数据输入表!H14) -> 鲸选超市（广州芳村店) | E11: =IF(D11="","",IFERROR(_xlfn.XLOOKUP(D11,客户信息底表!B:B,客户信息底表!Q:Q,,0),IFERROR(_xlfn.XLOOKUP(D11,客户信息底表!BB:BB,客户信息底表!Q:Q,,0),IFERROR(_xlfn.XLOOKUP(D11,客户信息底表!BC:BC,客户信息底表!Q:Q,,0),IFERROR(_xlfn.XLOOKUP(D11,客户信息底表!BD:BD,客户信息底表!Q:Q,,0),"底表未登记"))))) -> 113.23658 | F11: =IF(D11="","",IFERROR(_xlfn.XLOOKUP(D11,客户信息底表!B:B,客户信息底表!R:R,,0),IFERROR(_xlfn.XLOOKUP(D11,客户信息底表!BB:BB,客户信息底表!R:R,,0),IFERROR(_xlfn.XLOOKUP(D11,客户信息底表!BC:BC,客户信息底表!R:R,,0),IFERROR(_xlfn.XLOOKUP(D11,客户信息底表!BD:BD,客户信息底表!R:R,,0),"底表未登记"))))) -> 23.076887 | G11: =IF(D11="","",IFERROR(_xlfn.XLOOKUP(D11,客户信息底表!B:B,客户信息底表!L:L,,0),IFERROR(_xlfn.XLOOKUP(D11,客户信息底表!BB:BB,客户信息底表!L:L,,0),IFERROR(_xlfn.XLOOKUP(D11,客户信息底表!BC:BC,客户信息底表!L:L,,0),IFERROR(_xlfn.XLOOKUP(D11,客户信息底表!BD:BD,客户信息底表!L:L,,0),"底表未登记"))))) -> 花溪路3号 坑口工业区1栋2楼215鲸选超市里面(有电梯) | H11: =IF(D11="","",IFERROR(_xlfn.XLOOKUP(D11,客户信息底表!B:B,客户信息底表!G:G,,0),IFERROR(_xlfn.XLOOKUP(D11,客户信息底表!BB:BB,客户信息底表!G:G,,0),IFERROR(_xlfn.XLOOKUP(D11,客户信息底表!BC:BC,客户信息底表!G:G,,0),IFERROR(_xlfn.XLOOKUP(D11,客户信息底表!BD:BD,客户信息底表!G:G,,0),"底表未登记"))))) -> 13533764129 | I11: =IF(D11="","","整："&数据输入表!J14&"，散："&数据输入表!K14&"；重量kg："&数据输入表!L14&"，体积："&数据输入表!M14) -> 整：6，散：162；重量kg：162，体积：0.02 | J11: 46136 | O11: WH
A12: =IF(D12<>"",$A$2,"") -> LC20260421000980 | B12: FS-WB-SAMPLE-11 | C12: =IF(D12<>"",ROW()-1,"") -> 11 | D12: =IF(数据输入表!H15="","",数据输入表!H15) -> 畅盈到家超市（广州海珠店） | E12: =IF(D12="","",IFERROR(_xlfn.XLOOKUP(D12,客户信息底表!B:B,客户信息底表!Q:Q,,0),IFERROR(_xlfn.XLOOKUP(D12,客户信息底表!BB:BB,客户信息底表!Q:Q,,0),IFERROR(_xlfn.XLOOKUP(D12,客户信息底表!BC:BC,客户信息底表!Q:Q,,0),IFERROR(_xlfn.XLOOKUP(D12,客户信息底表!BD:BD,客户信息底表!Q:Q,,0),"底表未登记"))))) -> 113.26735 | F12: =IF(D12="","",IFERROR(_xlfn.XLOOKUP(D12,客户信息底表!B:B,客户信息底表!R:R,,0),IFERROR(_xlfn.XLOOKUP(D12,客户信息底表!BB:BB,客户信息底表!R:R,,0),IFERROR(_xlfn.XLOOKUP(D12,客户信息底表!BC:BC,客户信息底表!R:R,,0),IFERROR(_xlfn.XLOOKUP(D12,客户信息底表!BD:BD,客户信息底表!R:R,,0),"底表未登记"))))) -> 23.079249 | G12: =IF(D12="","",IFERROR(_xlfn.XLOOKUP(D12,客户信息底表!B:B,客户信息底表!L:L,,0),IFERROR(_xlfn.XLOOKUP(D12,客户信息底表!BB:BB,客户信息底表!L:L,,0),IFERROR(_xlfn.XLOOKUP(D12,客户信息底表!BC:BC,客户信息底表!L:L,,0),IFERROR(_xlfn.XLOOKUP(D12,客户信息底表!BD:BD,客户信息底表!L:L,,0),"底表未登记"))))) -> 南石头街道工业大道中路385号大院11号楼224房 | H12: =IF(D12="","",IFERROR(_xlfn.XLOOKUP(D12,客户信息底表!B:B,客户信息底表!G:G,,0),IFERROR(_xlfn.XLOOKUP(D12,客户信息底表!BB:BB,客户信息底表!G:G,,0),IFERROR(_xlfn.XLOOKUP(D12,客户信息底表!BC:BC,客户信息底表!G:G,,0),IFERROR(_xlfn.XLOOKUP(D12,客户信息底表!BD:BD,客户信息底表!G:G,,0),"底表未登记"))))) -> 13435657776 | I12: =IF(D12="","","整："&数据输入表!J15&"，散："&数据输入表!K15&"；重量kg："&数据输入表!L15&"，体积："&数据输入表!M15) -> 整：9，散：178；重量kg：178，体积：0.12 | J12: 46136 | O12: WH
A13: =IF(D13<>"",$A$2,"") -> LC20260421000980 | B13: FS-WB-SAMPLE-12 | C13: =IF(D13<>"",ROW()-1,"") -> 12 | D13: =IF(数据输入表!H16="","",数据输入表!H16) -> 值小团（广州海珠店） | E13: =IF(D13="","",IFERROR(_xlfn.XLOOKUP(D13,客户信息底表!B:B,客户信息底表!Q:Q,,0),IFERROR(_xlfn.XLOOKUP(D13,客户信息底表!BB:BB,客户信息底表!Q:Q,,0),IFERROR(_xlfn.XLOOKUP(D13,客户信息底表!BC:BC,客户信息底表!Q:Q,,0),IFERROR(_xlfn.XLOOKUP(D13,客户信息底表!BD:BD,客户信息底表!Q:Q,,0),"底表未登记"))))) -> 113.276 | F13: =IF(D13="","",IFERROR(_xlfn.XLOOKUP(D13,客户信息底表!B:B,客户信息底表!R:R,,0),IFERROR(_xlfn.XLOOKUP(D13,客户信息底表!BB:BB,客户信息底表!R:R,,0),IFERROR(_xlfn.XLOOKUP(D13,客户信息底表!BC:BC,客户信息底表!R:R,,0),IFERROR(_xlfn.XLOOKUP(D13,客户信息底表!BD:BD,客户信息底表!R:R,,0),"底表未登记"))))) -> 23.085416 | G13: =IF(D13="","",IFERROR(_xlfn.XLOOKUP(D13,客户信息底表!B:B,客户信息底表!L:L,,0),IFERROR(_xlfn.XLOOKUP(D13,客户信息底表!BB:BB,客户信息底表!L:L,,0),IFERROR(_xlfn.XLOOKUP(D13,客户信息底表!BC:BC,客户信息底表!L:L,,0),IFERROR(_xlfn.XLOOKUP(D13,客户信息底表!BD:BD,客户信息底表!L:L,,0),"底表未登记"))))) -> 信雅路54 | H13: =IF(D13="","",IFERROR(_xlfn.XLOOKUP(D13,客户信息底表!B:B,客户信息底表!G:G,,0),IFERROR(_xlfn.XLOOKUP(D13,客户信息底表!BB:BB,客户信息底表!G:G,,0),IFERROR(_xlfn.XLOOKUP(D13,客户信息底表!BC:BC,客户信息底表!G:G,,0),IFERROR(_xlfn.XLOOKUP(D13,客户信息底表!BD:BD,客户信息底表!G:G,,0),"底表未登记"))))) -> 13710664156 | I13: =IF(D13="","","整："&数据输入表!J16&"，散："&数据输入表!K16&"；重量kg："&数据输入表!L16&"，体积："&数据输入表!M16) -> 整：12，散：135；重量kg：135，体积：0.17 | J13: 46136 | O13: WH
A14: =IF(D14<>"",$A$2,"") | C14: =IF(D14<>"",ROW()-1,"") | D14: =IF(数据输入表!H17="","",数据输入表!H17) | E14: =IF(D14="","",IFERROR(_xlfn.XLOOKUP(D14,客户信息底表!B:B,客户信息底表!Q:Q,,0),IFERROR(_xlfn.XLOOKUP(D14,客户信息底表!BB:BB,客户信息底表!Q:Q,,0),IFERROR(_xlfn.XLOOKUP(D14,客户信息底表!BC:BC,客户信息底表!Q:Q,,0),IFERROR(_xlfn.XLOOKUP(D14,客户信息底表!BD:BD,客户信息底表!Q:Q,,0),"底表未登记"))))) | F14: =IF(D14="","",IFERROR(_xlfn.XLOOKUP(D14,客户信息底表!B:B,客户信息底表!R:R,,0),IFERROR(_xlfn.XLOOKUP(D14,客户信息底表!BB:BB,客户信息底表!R:R,,0),IFERROR(_xlfn.XLOOKUP(D14,客户信息底表!BC:BC,客户信息底表!R:R,,0),IFERROR(_xlfn.XLOOKUP(D14,客户信息底表!BD:BD,客户信息底表!R:R,,0),"底表未登记"))))) | G14: =IF(D14="","",IFERROR(_xlfn.XLOOKUP(D14,客户信息底表!B:B,客户信息底表!L:L,,0),IFERROR(_xlfn.XLOOKUP(D14,客户信息底表!BB:BB,客户信息底表!L:L,,0),IFERROR(_xlfn.XLOOKUP(D14,客户信息底表!BC:BC,客户信息底表!L:L,,0),IFERROR(_xlfn.XLOOKUP(D14,客户信息底表!BD:BD,客户信息底表!L:L,,0),"底表未登记"))))) | H14: =IF(D14="","",IFERROR(_xlfn.XLOOKUP(D14,客户信息底表!B:B,客户信息底表!G:G,,0),IFERROR(_xlfn.XLOOKUP(D14,客户信息底表!BB:BB,客户信息底表!G:G,,0),IFERROR(_xlfn.XLOOKUP(D14,客户信息底表!BC:BC,客户信息底表!G:G,,0),IFERROR(_xlfn.XLOOKUP(D14,客户信息底表!BD:BD,客户信息底表!G:G,,0),"底表未登记"))))) | I14: =IF(D14="","","整："&数据输入表!J17&"，散："&数据输入表!K17&"；重量kg："&数据输入表!L17&"，体积："&数据输入表!M17)
A15: =IF(D15<>"",$A$2,"") | C15: =IF(D15<>"",ROW()-1,"") | D15: =IF(数据输入表!H18="","",数据输入表!H18) | E15: =IF(D15="","",IFERROR(_xlfn.XLOOKUP(D15,客户信息底表!B:B,客户信息底表!Q:Q,,0),IFERROR(_xlfn.XLOOKUP(D15,客户信息底表!BB:BB,客户信息底表!Q:Q,,0),IFERROR(_xlfn.XLOOKUP(D15,客户信息底表!BC:BC,客户信息底表!Q:Q,,0),IFERROR(_xlfn.XLOOKUP(D15,客户信息底表!BD:BD,客户信息底表!Q:Q,,0),"底表未登记"))))) | F15: =IF(D15="","",IFERROR(_xlfn.XLOOKUP(D15,客户信息底表!B:B,客户信息底表!R:R,,0),IFERROR(_xlfn.XLOOKUP(D15,客户信息底表!BB:BB,客户信息底表!R:R,,0),IFERROR(_xlfn.XLOOKUP(D15,客户信息底表!BC:BC,客户信息底表!R:R,,0),IFERROR(_xlfn.XLOOKUP(D15,客户信息底表!BD:BD,客户信息底表!R:R,,0),"底表未登记"))))) | G15: =IF(D15="","",IFERROR(_xlfn.XLOOKUP(D15,客户信息底表!B:B,客户信息底表!L:L,,0),IFERROR(_xlfn.XLOOKUP(D15,客户信息底表!BB:BB,客户信息底表!L:L,,0),IFERROR(_xlfn.XLOOKUP(D15,客户信息底表!BC:BC,客户信息底表!L:L,,0),IFERROR(_xlfn.XLOOKUP(D15,客户信息底表!BD:BD,客户信息底表!L:L,,0),"底表未登记"))))) | H15: =IF(D15="","",IFERROR(_xlfn.XLOOKUP(D15,客户信息底表!B:B,客户信息底表!G:G,,0),IFERROR(_xlfn.XLOOKUP(D15,客户信息底表!BB:BB,客户信息底表!G:G,,0),IFERROR(_xlfn.XLOOKUP(D15,客户信息底表!BC:BC,客户信息底表!G:G,,0),IFERROR(_xlfn.XLOOKUP(D15,客户信息底表!BD:BD,客户信息底表!G:G,,0),"底表未登记"))))) | I15: =IF(D15="","","整："&数据输入表!J18&"，散："&数据输入表!K18&"；重量kg："&数据输入表!L18&"，体积："&数据输入表!M18)
A16: =IF(D16<>"",$A$2,"") | C16: =IF(D16<>"",ROW()-1,"") | D16: =IF(数据输入表!H19="","",数据输入表!H19) | E16: =IF(D16="","",IFERROR(_xlfn.XLOOKUP(D16,客户信息底表!B:B,客户信息底表!Q:Q,,0),IFERROR(_xlfn.XLOOKUP(D16,客户信息底表!BB:BB,客户信息底表!Q:Q,,0),IFERROR(_xlfn.XLOOKUP(D16,客户信息底表!BC:BC,客户信息底表!Q:Q,,0),IFERROR(_xlfn.XLOOKUP(D16,客户信息底表!BD:BD,客户信息底表!Q:Q,,0),"底表未登记"))))) | F16: =IF(D16="","",IFERROR(_xlfn.XLOOKUP(D16,客户信息底表!B:B,客户信息底表!R:R,,0),IFERROR(_xlfn.XLOOKUP(D16,客户信息底表!BB:BB,客户信息底表!R:R,,0),IFERROR(_xlfn.XLOOKUP(D16,客户信息底表!BC:BC,客户信息底表!R:R,,0),IFERROR(_xlfn.XLOOKUP(D16,客户信息底表!BD:BD,客户信息底表!R:R,,0),"底表未登记"))))) | G16: =IF(D16="","",IFERROR(_xlfn.XLOOKUP(D16,客户信息底表!B:B,客户信息底表!L:L,,0),IFERROR(_xlfn.XLOOKUP(D16,客户信息底表!BB:BB,客户信息底表!L:L,,0),IFERROR(_xlfn.XLOOKUP(D16,客户信息底表!BC:BC,客户信息底表!L:L,,0),IFERROR(_xlfn.XLOOKUP(D16,客户信息底表!BD:BD,客户信息底表!L:L,,0),"底表未登记"))))) | H16: =IF(D16="","",IFERROR(_xlfn.XLOOKUP(D16,客户信息底表!B:B,客户信息底表!G:G,,0),IFERROR(_xlfn.XLOOKUP(D16,客户信息底表!BB:BB,客户信息底表!G:G,,0),IFERROR(_xlfn.XLOOKUP(D16,客户信息底表!BC:BC,客户信息底表!G:G,,0),IFERROR(_xlfn.XLOOKUP(D16,客户信息底表!BD:BD,客户信息底表!G:G,,0),"底表未登记"))))) | I16: =IF(D16="","","整："&数据输入表!J19&"，散："&数据输入表!K19&"；重量kg："&数据输入表!L19&"，体积："&数据输入表!M19)
A17: =IF(D17<>"",$A$2,"") | C17: =IF(D17<>"",ROW()-1,"") | D17: =IF(数据输入表!H20="","",数据输入表!H20) | E17: =IF(D17="","",IFERROR(_xlfn.XLOOKUP(D17,客户信息底表!B:B,客户信息底表!Q:Q,,0),IFERROR(_xlfn.XLOOKUP(D17,客户信息底表!BB:BB,客户信息底表!Q:Q,,0),IFERROR(_xlfn.XLOOKUP(D17,客户信息底表!BC:BC,客户信息底表!Q:Q,,0),IFERROR(_xlfn.XLOOKUP(D17,客户信息底表!BD:BD,客户信息底表!Q:Q,,0),"底表未登记"))))) | F17: =IF(D17="","",IFERROR(_xlfn.XLOOKUP(D17,客户信息底表!B:B,客户信息底表!R:R,,0),IFERROR(_xlfn.XLOOKUP(D17,客户信息底表!BB:BB,客户信息底表!R:R,,0),IFERROR(_xlfn.XLOOKUP(D17,客户信息底表!BC:BC,客户信息底表!R:R,,0),IFERROR(_xlfn.XLOOKUP(D17,客户信息底表!BD:BD,客户信息底表!R:R,,0),"底表未登记"))))) | G17: =IF(D17="","",IFERROR(_xlfn.XLOOKUP(D17,客户信息底表!B:B,客户信息底表!L:L,,0),IFERROR(_xlfn.XLOOKUP(D17,客户信息底表!BB:BB,客户信息底表!L:L,,0),IFERROR(_xlfn.XLOOKUP(D17,客户信息底表!BC:BC,客户信息底表!L:L,,0),IFERROR(_xlfn.XLOOKUP(D17,客户信息底表!BD:BD,客户信息底表!L:L,,0),"底表未登记"))))) | H17: =IF(D17="","",IFERROR(_xlfn.XLOOKUP(D17,客户信息底表!B:B,客户信息底表!G:G,,0),IFERROR(_xlfn.XLOOKUP(D17,客户信息底表!BB:BB,客户信息底表!G:G,,0),IFERROR(_xlfn.XLOOKUP(D17,客户信息底表!BC:BC,客户信息底表!G:G,,0),IFERROR(_xlfn.XLOOKUP(D17,客户信息底表!BD:BD,客户信息底表!G:G,,0),"底表未登记"))))) | I17: =IF(D17="","","整："&数据输入表!J20&"，散："&数据输入表!K20&"；重量kg："&数据输入表!L20&"，体积："&数据输入表!M20)
A18: =IF(D18<>"",$A$2,"") | C18: =IF(D18<>"",ROW()-1,"") | D18: =IF(数据输入表!H21="","",数据输入表!H21) | E18: =IF(D18="","",IFERROR(_xlfn.XLOOKUP(D18,客户信息底表!B:B,客户信息底表!Q:Q,,0),IFERROR(_xlfn.XLOOKUP(D18,客户信息底表!BB:BB,客户信息底表!Q:Q,,0),IFERROR(_xlfn.XLOOKUP(D18,客户信息底表!BC:BC,客户信息底表!Q:Q,,0),IFERROR(_xlfn.XLOOKUP(D18,客户信息底表!BD:BD,客户信息底表!Q:Q,,0),"底表未登记"))))) | F18: =IF(D18="","",IFERROR(_xlfn.XLOOKUP(D18,客户信息底表!B:B,客户信息底表!R:R,,0),IFERROR(_xlfn.XLOOKUP(D18,客户信息底表!BB:BB,客户信息底表!R:R,,0),IFERROR(_xlfn.XLOOKUP(D18,客户信息底表!BC:BC,客户信息底表!R:R,,0),IFERROR(_xlfn.XLOOKUP(D18,客户信息底表!BD:BD,客户信息底表!R:R,,0),"底表未登记"))))) | G18: =IF(D18="","",IFERROR(_xlfn.XLOOKUP(D18,客户信息底表!B:B,客户信息底表!L:L,,0),IFERROR(_xlfn.XLOOKUP(D18,客户信息底表!BB:BB,客户信息底表!L:L,,0),IFERROR(_xlfn.XLOOKUP(D18,客户信息底表!BC:BC,客户信息底表!L:L,,0),IFERROR(_xlfn.XLOOKUP(D18,客户信息底表!BD:BD,客户信息底表!L:L,,0),"底表未登记"))))) | H18: =IF(D18="","",IFERROR(_xlfn.XLOOKUP(D18,客户信息底表!B:B,客户信息底表!G:G,,0),IFERROR(_xlfn.XLOOKUP(D18,客户信息底表!BB:BB,客户信息底表!G:G,,0),IFERROR(_xlfn.XLOOKUP(D18,客户信息底表!BC:BC,客户信息底表!G:G,,0),IFERROR(_xlfn.XLOOKUP(D18,客户信息底表!BD:BD,客户信息底表!G:G,,0),"底表未登记"))))) | I18: =IF(D18="","","整："&数据输入表!J21&"，散："&数据输入表!K21&"；重量kg："&数据输入表!L21&"，体积："&数据输入表!M21)
A19: =IF(D19<>"",$A$2,"") | C19: =IF(D19<>"",ROW()-1,"") | D19: =IF(数据输入表!H22="","",数据输入表!H22) | E19: =IF(D19="","",IFERROR(_xlfn.XLOOKUP(D19,客户信息底表!B:B,客户信息底表!Q:Q,,0),IFERROR(_xlfn.XLOOKUP(D19,客户信息底表!BB:BB,客户信息底表!Q:Q,,0),IFERROR(_xlfn.XLOOKUP(D19,客户信息底表!BC:BC,客户信息底表!Q:Q,,0),IFERROR(_xlfn.XLOOKUP(D19,客户信息底表!BD:BD,客户信息底表!Q:Q,,0),"底表未登记"))))) | F19: =IF(D19="","",IFERROR(_xlfn.XLOOKUP(D19,客户信息底表!B:B,客户信息底表!R:R,,0),IFERROR(_xlfn.XLOOKUP(D19,客户信息底表!BB:BB,客户信息底表!R:R,,0),IFERROR(_xlfn.XLOOKUP(D19,客户信息底表!BC:BC,客户信息底表!R:R,,0),IFERROR(_xlfn.XLOOKUP(D19,客户信息底表!BD:BD,客户信息底表!R:R,,0),"底表未登记"))))) | G19: =IF(D19="","",IFERROR(_xlfn.XLOOKUP(D19,客户信息底表!B:B,客户信息底表!L:L,,0),IFERROR(_xlfn.XLOOKUP(D19,客户信息底表!BB:BB,客户信息底表!L:L,,0),IFERROR(_xlfn.XLOOKUP(D19,客户信息底表!BC:BC,客户信息底表!L:L,,0),IFERROR(_xlfn.XLOOKUP(D19,客户信息底表!BD:BD,客户信息底表!L:L,,0),"底表未登记"))))) | H19: =IF(D19="","",IFERROR(_xlfn.XLOOKUP(D19,客户信息底表!B:B,客户信息底表!G:G,,0),IFERROR(_xlfn.XLOOKUP(D19,客户信息底表!BB:BB,客户信息底表!G:G,,0),IFERROR(_xlfn.XLOOKUP(D19,客户信息底表!BC:BC,客户信息底表!G:G,,0),IFERROR(_xlfn.XLOOKUP(D19,客户信息底表!BD:BD,客户信息底表!G:G,,0),"底表未登记"))))) | I19: =IF(D19="","","整："&数据输入表!J22&"，散："&数据输入表!K22&"；重量kg："&数据输入表!L22&"，体积："&数据输入表!M22)
A20: =IF(D20<>"",$A$2,"") | C20: =IF(D20<>"",ROW()-1,"") | D20: =IF(数据输入表!H23="","",数据输入表!H23) | E20: =IF(D20="","",IFERROR(_xlfn.XLOOKUP(D20,客户信息底表!B:B,客户信息底表!Q:Q,,0),IFERROR(_xlfn.XLOOKUP(D20,客户信息底表!BB:BB,客户信息底表!Q:Q,,0),IFERROR(_xlfn.XLOOKUP(D20,客户信息底表!BC:BC,客户信息底表!Q:Q,,0),IFERROR(_xlfn.XLOOKUP(D20,客户信息底表!BD:BD,客户信息底表!Q:Q,,0),"底表未登记"))))) | F20: =IF(D20="","",IFERROR(_xlfn.XLOOKUP(D20,客户信息底表!B:B,客户信息底表!R:R,,0),IFERROR(_xlfn.XLOOKUP(D20,客户信息底表!BB:BB,客户信息底表!R:R,,0),IFERROR(_xlfn.XLOOKUP(D20,客户信息底表!BC:BC,客户信息底表!R:R,,0),IFERROR(_xlfn.XLOOKUP(D20,客户信息底表!BD:BD,客户信息底表!R:R,,0),"底表未登记"))))) | G20: =IF(D20="","",IFERROR(_xlfn.XLOOKUP(D20,客户信息底表!B:B,客户信息底表!L:L,,0),IFERROR(_xlfn.XLOOKUP(D20,客户信息底表!BB:BB,客户信息底表!L:L,,0),IFERROR(_xlfn.XLOOKUP(D20,客户信息底表!BC:BC,客户信息底表!L:L,,0),IFERROR(_xlfn.XLOOKUP(D20,客户信息底表!BD:BD,客户信息底表!L:L,,0),"底表未登记"))))) | H20: =IF(D20="","",IFERROR(_xlfn.XLOOKUP(D20,客户信息底表!B:B,客户信息底表!G:G,,0),IFERROR(_xlfn.XLOOKUP(D20,客户信息底表!BB:BB,客户信息底表!G:G,,0),IFERROR(_xlfn.XLOOKUP(D20,客户信息底表!BC:BC,客户信息底表!G:G,,0),IFERROR(_xlfn.XLOOKUP(D20,客户信息底表!BD:BD,客户信息底表!G:G,,0),"底表未登记"))))) | I20: =IF(D20="","","整："&数据输入表!J23&"，散："&数据输入表!K23&"；重量kg："&数据输入表!L23&"，体积："&数据输入表!M23)
A21: =IF(D21<>"",$A$2,"") | C21: =IF(D21<>"",ROW()-1,"") | D21: =IF(数据输入表!H24="","",数据输入表!H24) | E21: =IF(D21="","",IFERROR(_xlfn.XLOOKUP(D21,客户信息底表!B:B,客户信息底表!Q:Q,,0),IFERROR(_xlfn.XLOOKUP(D21,客户信息底表!BB:BB,客户信息底表!Q:Q,,0),IFERROR(_xlfn.XLOOKUP(D21,客户信息底表!BC:BC,客户信息底表!Q:Q,,0),IFERROR(_xlfn.XLOOKUP(D21,客户信息底表!BD:BD,客户信息底表!Q:Q,,0),"底表未登记"))))) | F21: =IF(D21="","",IFERROR(_xlfn.XLOOKUP(D21,客户信息底表!B:B,客户信息底表!R:R,,0),IFERROR(_xlfn.XLOOKUP(D21,客户信息底表!BB:BB,客户信息底表!R:R,,0),IFERROR(_xlfn.XLOOKUP(D21,客户信息底表!BC:BC,客户信息底表!R:R,,0),IFERROR(_xlfn.XLOOKUP(D21,客户信息底表!BD:BD,客户信息底表!R:R,,0),"底表未登记"))))) | G21: =IF(D21="","",IFERROR(_xlfn.XLOOKUP(D21,客户信息底表!B:B,客户信息底表!L:L,,0),IFERROR(_xlfn.XLOOKUP(D21,客户信息底表!BB:BB,客户信息底表!L:L,,0),IFERROR(_xlfn.XLOOKUP(D21,客户信息底表!BC:BC,客户信息底表!L:L,,0),IFERROR(_xlfn.XLOOKUP(D21,客户信息底表!BD:BD,客户信息底表!L:L,,0),"底表未登记"))))) | H21: =IF(D21="","",IFERROR(_xlfn.XLOOKUP(D21,客户信息底表!B:B,客户信息底表!G:G,,0),IFERROR(_xlfn.XLOOKUP(D21,客户信息底表!BB:BB,客户信息底表!G:G,,0),IFERROR(_xlfn.XLOOKUP(D21,客户信息底表!BC:BC,客户信息底表!G:G,,0),IFERROR(_xlfn.XLOOKUP(D21,客户信息底表!BD:BD,客户信息底表!G:G,,0),"底表未登记"))))) | I21: =IF(D21="","","整："&数据输入表!J24&"，散："&数据输入表!K24&"；重量kg："&数据输入表!L24&"，体积："&数据输入表!M24)
A22: =IF(D22<>"",$A$2,"") | C22: =IF(D22<>"",ROW()-1,"") | D22: =IF(数据输入表!H25="","",数据输入表!H25) | E22: =IF(D22="","",IFERROR(_xlfn.XLOOKUP(D22,客户信息底表!B:B,客户信息底表!Q:Q,,0),IFERROR(_xlfn.XLOOKUP(D22,客户信息底表!BB:BB,客户信息底表!Q:Q,,0),IFERROR(_xlfn.XLOOKUP(D22,客户信息底表!BC:BC,客户信息底表!Q:Q,,0),IFERROR(_xlfn.XLOOKUP(D22,客户信息底表!BD:BD,客户信息底表!Q:Q,,0),"底表未登记"))))) | F22: =IF(D22="","",IFERROR(_xlfn.XLOOKUP(D22,客户信息底表!B:B,客户信息底表!R:R,,0),IFERROR(_xlfn.XLOOKUP(D22,客户信息底表!BB:BB,客户信息底表!R:R,,0),IFERROR(_xlfn.XLOOKUP(D22,客户信息底表!BC:BC,客户信息底表!R:R,,0),IFERROR(_xlfn.XLOOKUP(D22,客户信息底表!BD:BD,客户信息底表!R:R,,0),"底表未登记"))))) | G22: =IF(D22="","",IFERROR(_xlfn.XLOOKUP(D22,客户信息底表!B:B,客户信息底表!L:L,,0),IFERROR(_xlfn.XLOOKUP(D22,客户信息底表!BB:BB,客户信息底表!L:L,,0),IFERROR(_xlfn.XLOOKUP(D22,客户信息底表!BC:BC,客户信息底表!L:L,,0),IFERROR(_xlfn.XLOOKUP(D22,客户信息底表!BD:BD,客户信息底表!L:L,,0),"底表未登记"))))) | H22: =IF(D22="","",IFERROR(_xlfn.XLOOKUP(D22,客户信息底表!B:B,客户信息底表!G:G,,0),IFERROR(_xlfn.XLOOKUP(D22,客户信息底表!BB:BB,客户信息底表!G:G,,0),IFERROR(_xlfn.XLOOKUP(D22,客户信息底表!BC:BC,客户信息底表!G:G,,0),IFERROR(_xlfn.XLOOKUP(D22,客户信息底表!BD:BD,客户信息底表!G:G,,0),"底表未登记"))))) | I22: =IF(D22="","","整："&数据输入表!J25&"，散："&数据输入表!K25&"；重量kg："&数据输入表!L25&"，体积："&数据输入表!M25)
A23: =IF(D23<>"",$A$2,"") | C23: =IF(D23<>"",ROW()-1,"") | D23: =IF(数据输入表!H26="","",数据输入表!H26) | E23: =IF(D23="","",IFERROR(_xlfn.XLOOKUP(D23,客户信息底表!B:B,客户信息底表!Q:Q,,0),IFERROR(_xlfn.XLOOKUP(D23,客户信息底表!BB:BB,客户信息底表!Q:Q,,0),IFERROR(_xlfn.XLOOKUP(D23,客户信息底表!BC:BC,客户信息底表!Q:Q,,0),IFERROR(_xlfn.XLOOKUP(D23,客户信息底表!BD:BD,客户信息底表!Q:Q,,0),"底表未登记"))))) | F23: =IF(D23="","",IFERROR(_xlfn.XLOOKUP(D23,客户信息底表!B:B,客户信息底表!R:R,,0),IFERROR(_xlfn.XLOOKUP(D23,客户信息底表!BB:BB,客户信息底表!R:R,,0),IFERROR(_xlfn.XLOOKUP(D23,客户信息底表!BC:BC,客户信息底表!R:R,,0),IFERROR(_xlfn.XLOOKUP(D23,客户信息底表!BD:BD,客户信息底表!R:R,,0),"底表未登记"))))) | G23: =IF(D23="","",IFERROR(_xlfn.XLOOKUP(D23,客户信息底表!B:B,客户信息底表!L:L,,0),IFERROR(_xlfn.XLOOKUP(D23,客户信息底表!BB:BB,客户信息底表!L:L,,0),IFERROR(_xlfn.XLOOKUP(D23,客户信息底表!BC:BC,客户信息底表!L:L,,0),IFERROR(_xlfn.XLOOKUP(D23,客户信息底表!BD:BD,客户信息底表!L:L,,0),"底表未登记"))))) | H23: =IF(D23="","",IFERROR(_xlfn.XLOOKUP(D23,客户信息底表!B:B,客户信息底表!G:G,,0),IFERROR(_xlfn.XLOOKUP(D23,客户信息底表!BB:BB,客户信息底表!G:G,,0),IFERROR(_xlfn.XLOOKUP(D23,客户信息底表!BC:BC,客户信息底表!G:G,,0),IFERROR(_xlfn.XLOOKUP(D23,客户信息底表!BD:BD,客户信息底表!G:G,,0),"底表未登记"))))) | I23: =IF(D23="","","整："&数据输入表!J26&"，散："&数据输入表!K26&"；重量kg："&数据输入表!L26&"，体积："&数据输入表!M26)
A24: =IF(D24<>"",$A$2,"") | C24: =IF(D24<>"",ROW()-1,"") | D24: =IF(数据输入表!H27="","",数据输入表!H27) | E24: =IF(D24="","",IFERROR(_xlfn.XLOOKUP(D24,客户信息底表!B:B,客户信息底表!Q:Q,,0),IFERROR(_xlfn.XLOOKUP(D24,客户信息底表!BB:BB,客户信息底表!Q:Q,,0),IFERROR(_xlfn.XLOOKUP(D24,客户信息底表!BC:BC,客户信息底表!Q:Q,,0),IFERROR(_xlfn.XLOOKUP(D24,客户信息底表!BD:BD,客户信息底表!Q:Q,,0),"底表未登记"))))) | F24: =IF(D24="","",IFERROR(_xlfn.XLOOKUP(D24,客户信息底表!B:B,客户信息底表!R:R,,0),IFERROR(_xlfn.XLOOKUP(D24,客户信息底表!BB:BB,客户信息底表!R:R,,0),IFERROR(_xlfn.XLOOKUP(D24,客户信息底表!BC:BC,客户信息底表!R:R,,0),IFERROR(_xlfn.XLOOKUP(D24,客户信息底表!BD:BD,客户信息底表!R:R,,0),"底表未登记"))))) | G24: =IF(D24="","",IFERROR(_xlfn.XLOOKUP(D24,客户信息底表!B:B,客户信息底表!L:L,,0),IFERROR(_xlfn.XLOOKUP(D24,客户信息底表!BB:BB,客户信息底表!L:L,,0),IFERROR(_xlfn.XLOOKUP(D24,客户信息底表!BC:BC,客户信息底表!L:L,,0),IFERROR(_xlfn.XLOOKUP(D24,客户信息底表!BD:BD,客户信息底表!L:L,,0),"底表未登记"))))) | H24: =IF(D24="","",IFERROR(_xlfn.XLOOKUP(D24,客户信息底表!B:B,客户信息底表!G:G,,0),IFERROR(_xlfn.XLOOKUP(D24,客户信息底表!BB:BB,客户信息底表!G:G,,0),IFERROR(_xlfn.XLOOKUP(D24,客户信息底表!BC:BC,客户信息底表!G:G,,0),IFERROR(_xlfn.XLOOKUP(D24,客户信息底表!BD:BD,客户信息底表!G:G,,0),"底表未登记"))))) | I24: =IF(D24="","","整："&数据输入表!J27&"，散："&数据输入表!K27&"；重量kg："&数据输入表!L27&"，体积："&数据输入表!M27)
A25: =IF(D25<>"",$A$2,"") | C25: =IF(D25<>"",ROW()-1,"") | D25: =IF(数据输入表!H28="","",数据输入表!H28) | E25: =IF(D25="","",IFERROR(_xlfn.XLOOKUP(D25,客户信息底表!B:B,客户信息底表!Q:Q,,0),IFERROR(_xlfn.XLOOKUP(D25,客户信息底表!BB:BB,客户信息底表!Q:Q,,0),IFERROR(_xlfn.XLOOKUP(D25,客户信息底表!BC:BC,客户信息底表!Q:Q,,0),IFERROR(_xlfn.XLOOKUP(D25,客户信息底表!BD:BD,客户信息底表!Q:Q,,0),"底表未登记"))))) | F25: =IF(D25="","",IFERROR(_xlfn.XLOOKUP(D25,客户信息底表!B:B,客户信息底表!R:R,,0),IFERROR(_xlfn.XLOOKUP(D25,客户信息底表!BB:BB,客户信息底表!R:R,,0),IFERROR(_xlfn.XLOOKUP(D25,客户信息底表!BC:BC,客户信息底表!R:R,,0),IFERROR(_xlfn.XLOOKUP(D25,客户信息底表!BD:BD,客户信息底表!R:R,,0),"底表未登记"))))) | G25: =IF(D25="","",IFERROR(_xlfn.XLOOKUP(D25,客户信息底表!B:B,客户信息底表!L:L,,0),IFERROR(_xlfn.XLOOKUP(D25,客户信息底表!BB:BB,客户信息底表!L:L,,0),IFERROR(_xlfn.XLOOKUP(D25,客户信息底表!BC:BC,客户信息底表!L:L,,0),IFERROR(_xlfn.XLOOKUP(D25,客户信息底表!BD:BD,客户信息底表!L:L,,0),"底表未登记"))))) | H25: =IF(D25="","",IFERROR(_xlfn.XLOOKUP(D25,客户信息底表!B:B,客户信息底表!G:G,,0),IFERROR(_xlfn.XLOOKUP(D25,客户信息底表!BB:BB,客户信息底表!G:G,,0),IFERROR(_xlfn.XLOOKUP(D25,客户信息底表!BC:BC,客户信息底表!G:G,,0),IFERROR(_xlfn.XLOOKUP(D25,客户信息底表!BD:BD,客户信息底表!G:G,,0),"底表未登记"))))) | I25: =IF(D25="","","整："&数据输入表!J28&"，散："&数据输入表!K28&"；重量kg："&数据输入表!L28&"，体积："&数据输入表!M28)
... A37: =IF(D37<>"",$A$2,"") | C37: =IF(D37<>"",ROW()-1,"") | D37: =IF(数据输入表!H40="","",数据输入表!H40) | E37: =IF(D37="","",IFERROR(_xlfn.XLOOKUP(D37,客户信息底表!B:B,客户信息底表!Q:Q,,0),IFERROR(_xlfn.XLOOKUP(D37,客户信息底表!BB:BB,客户信息底表!Q:Q,,0),IFERROR(_xlfn.XLOOKUP(D37,客户信息底表!BC:BC,客户信息底表!Q:Q,,0),IFERROR(_xlfn.XLOOKUP(D37,客户信息底表!BD:BD,客户信息底表!Q:Q,,0),"底表未登记"))))) | F37: =IF(D37="","",IFERROR(_xlfn.XLOOKUP(D37,客户信息底表!B:B,客户信息底表!R:R,,0),IFERROR(_xlfn.XLOOKUP(D37,客户信息底表!BB:BB,客户信息底表!R:R,,0),IFERROR(_xlfn.XLOOKUP(D37,客户信息底表!BC:BC,客户信息底表!R:R,,0),IFERROR(_xlfn.XLOOKUP(D37,客户信息底表!BD:BD,客户信息底表!R:R,,0),"底表未登记"))))) | G37: =IF(D37="","",IFERROR(_xlfn.XLOOKUP(D37,客户信息底表!B:B,客户信息底表!L:L,,0),IFERROR(_xlfn.XLOOKUP(D37,客户信息底表!BB:BB,客户信息底表!L:L,,0),IFERROR(_xlfn.XLOOKUP(D37,客户信息底表!BC:BC,客户信息底表!L:L,,0),IFERROR(_xlfn.XLOOKUP(D37,客户信息底表!BD:BD,客户信息底表!L:L,,0),"底表未登记"))))) | H37: =IF(D37="","",IFERROR(_xlfn.XLOOKUP(D37,客户信息底表!B:B,客户信息底表!G:G,,0),IFERROR(_xlfn.XLOOKUP(D37,客户信息底表!BB:BB,客户信息底表!G:G,,0),IFERROR(_xlfn.XLOOKUP(D37,客户信息底表!BC:BC,客户信息底表!G:G,,0),IFERROR(_xlfn.XLOOKUP(D37,客户信息底表!BD:BD,客户信息底表!G:G,,0),"底表未登记"))))) | I37: =IF(D37="","","整："&数据输入表!J40&"，散："&数据输入表!K40&"；重量kg："&数据输入表!L40&"，体积："&数据输入表!M40)
A38: =IF(D38<>"",$A$2,"") | C38: =IF(D38<>"",ROW()-1,"") | E38: =IF(D38="","",IFERROR(_xlfn.XLOOKUP(D38,客户信息底表!B:B,客户信息底表!Q:Q,,0),IFERROR(_xlfn.XLOOKUP(D38,客户信息底表!BB:BB,客户信息底表!Q:Q,,0),IFERROR(_xlfn.XLOOKUP(D38,客户信息底表!BC:BC,客户信息底表!Q:Q,,0),IFERROR(_xlfn.XLOOKUP(D38,客户信息底表!BD:BD,客户信息底表!Q:Q,,0),"底表未登记"))))) | F38: =IF(D38="","",IFERROR(_xlfn.XLOOKUP(D38,客户信息底表!B:B,客户信息底表!R:R,,0),IFERROR(_xlfn.XLOOKUP(D38,客户信息底表!BB:BB,客户信息底表!R:R,,0),IFERROR(_xlfn.XLOOKUP(D38,客户信息底表!BC:BC,客户信息底表!R:R,,0),IFERROR(_xlfn.XLOOKUP(D38,客户信息底表!BD:BD,客户信息底表!R:R,,0),"底表未登记"))))) | G38: =IF(D38="","",IFERROR(_xlfn.XLOOKUP(D38,客户信息底表!B:B,客户信息底表!L:L,,0),IFERROR(_xlfn.XLOOKUP(D38,客户信息底表!BB:BB,客户信息底表!L:L,,0),IFERROR(_xlfn.XLOOKUP(D38,客户信息底表!BC:BC,客户信息底表!L:L,,0),IFERROR(_xlfn.XLOOKUP(D38,客户信息底表!BD:BD,客户信息底表!L:L,,0),"底表未登记"))))) | H38: =IF(D38="","",IFERROR(_xlfn.XLOOKUP(D38,客户信息底表!B:B,客户信息底表!G:G,,0),IFERROR(_xlfn.XLOOKUP(D38,客户信息底表!BB:BB,客户信息底表!G:G,,0),IFERROR(_xlfn.XLOOKUP(D38,客户信息底表!BC:BC,客户信息底表!G:G,,0),IFERROR(_xlfn.XLOOKUP(D38,客户信息底表!BD:BD,客户信息底表!G:G,,0),"底表未登记"))))) | I38: =IF(D38="","","整："&数据输入表!J41&"，散："&数据输入表!K41&"；重量kg："&数据输入表!L41&"，体积："&数据输入表!M41)
A39: =IF(D39<>"",$A$2,"") | C39: =IF(D39<>"",ROW()-1,"") | E39: =IF(D39="","",IFERROR(_xlfn.XLOOKUP(D39,客户信息底表!B:B,客户信息底表!Q:Q,,0),IFERROR(_xlfn.XLOOKUP(D39,客户信息底表!BB:BB,客户信息底表!Q:Q,,0),IFERROR(_xlfn.XLOOKUP(D39,客户信息底表!BC:BC,客户信息底表!Q:Q,,0),IFERROR(_xlfn.XLOOKUP(D39,客户信息底表!BD:BD,客户信息底表!Q:Q,,0),"底表未登记"))))) | F39: =IF(D39="","",IFERROR(_xlfn.XLOOKUP(D39,客户信息底表!B:B,客户信息底表!R:R,,0),IFERROR(_xlfn.XLOOKUP(D39,客户信息底表!BB:BB,客户信息底表!R:R,,0),IFERROR(_xlfn.XLOOKUP(D39,客户信息底表!BC:BC,客户信息底表!R:R,,0),IFERROR(_xlfn.XLOOKUP(D39,客户信息底表!BD:BD,客户信息底表!R:R,,0),"底表未登记"))))) | G39: =IF(D39="","",IFERROR(_xlfn.XLOOKUP(D39,客户信息底表!B:B,客户信息底表!L:L,,0),IFERROR(_xlfn.XLOOKUP(D39,客户信息底表!BB:BB,客户信息底表!L:L,,0),IFERROR(_xlfn.XLOOKUP(D39,客户信息底表!BC:BC,客户信息底表!L:L,,0),IFERROR(_xlfn.XLOOKUP(D39,客户信息底表!BD:BD,客户信息底表!L:L,,0),"底表未登记"))))) | H39: =IF(D39="","",IFERROR(_xlfn.XLOOKUP(D39,客户信息底表!B:B,客户信息底表!G:G,,0),IFERROR(_xlfn.XLOOKUP(D39,客户信息底表!BB:BB,客户信息底表!G:G,,0),IFERROR(_xlfn.XLOOKUP(D39,客户信息底表!BC:BC,客户信息底表!G:G,,0),IFERROR(_xlfn.XLOOKUP(D39,客户信息底表!BD:BD,客户信息底表!G:G,,0),"底表未登记"))))) | I39: =IF(D39="","","整："&数据输入表!J42&"，散："&数据输入表!K42&"；重量kg："&数据输入表!L42&"，体积："&数据输入表!M42)
A40: =IF(D40<>"",$A$2,"") | C40: =IF(D40<>"",ROW()-1,"") | E40: =IF(D40="","",IFERROR(_xlfn.XLOOKUP(D40,客户信息底表!B:B,客户信息底表!Q:Q,,0),IFERROR(_xlfn.XLOOKUP(D40,客户信息底表!BB:BB,客户信息底表!Q:Q,,0),IFERROR(_xlfn.XLOOKUP(D40,客户信息底表!BC:BC,客户信息底表!Q:Q,,0),IFERROR(_xlfn.XLOOKUP(D40,客户信息底表!BD:BD,客户信息底表!Q:Q,,0),"底表未登记"))))) | F40: =IF(D40="","",IFERROR(_xlfn.XLOOKUP(D40,客户信息底表!B:B,客户信息底表!R:R,,0),IFERROR(_xlfn.XLOOKUP(D40,客户信息底表!BB:BB,客户信息底表!R:R,,0),IFERROR(_xlfn.XLOOKUP(D40,客户信息底表!BC:BC,客户信息底表!R:R,,0),IFERROR(_xlfn.XLOOKUP(D40,客户信息底表!BD:BD,客户信息底表!R:R,,0),"底表未登记"))))) | G40: =IF(D40="","",IFERROR(_xlfn.XLOOKUP(D40,客户信息底表!B:B,客户信息底表!L:L,,0),IFERROR(_xlfn.XLOOKUP(D40,客户信息底表!BB:BB,客户信息底表!L:L,,0),IFERROR(_xlfn.XLOOKUP(D40,客户信息底表!BC:BC,客户信息底表!L:L,,0),IFERROR(_xlfn.XLOOKUP(D40,客户信息底表!BD:BD,客户信息底表!L:L,,0),"底表未登记"))))) | H40: =IF(D40="","",IFERROR(_xlfn.XLOOKUP(D40,客户信息底表!B:B,客户信息底表!G:G,,0),IFERROR(_xlfn.XLOOKUP(D40,客户信息底表!BB:BB,客户信息底表!G:G,,0),IFERROR(_xlfn.XLOOKUP(D40,客户信息底表!BC:BC,客户信息底表!G:G,,0),IFERROR(_xlfn.XLOOKUP(D40,客户信息底表!BD:BD,客户信息底表!G:G,,0),"底表未登记"))))) | I40: =IF(D40="","","整："&数据输入表!J43&"，散："&数据输入表!K43&"；重量kg："&数据输入表!L43&"，体积："&数据输入表!M43)
A41: =IF(D41<>"",$A$2,"") | C41: =IF(D41<>"",ROW()-1,"") | E41: =IF(D41="","",IFERROR(_xlfn.XLOOKUP(D41,客户信息底表!B:B,客户信息底表!Q:Q,,0),IFERROR(_xlfn.XLOOKUP(D41,客户信息底表!BB:BB,客户信息底表!Q:Q,,0),IFERROR(_xlfn.XLOOKUP(D41,客户信息底表!BC:BC,客户信息底表!Q:Q,,0),IFERROR(_xlfn.XLOOKUP(D41,客户信息底表!BD:BD,客户信息底表!Q:Q,,0),"底表未登记"))))) | F41: =IF(D41="","",IFERROR(_xlfn.XLOOKUP(D41,客户信息底表!B:B,客户信息底表!R:R,,0),IFERROR(_xlfn.XLOOKUP(D41,客户信息底表!BB:BB,客户信息底表!R:R,,0),IFERROR(_xlfn.XLOOKUP(D41,客户信息底表!BC:BC,客户信息底表!R:R,,0),IFERROR(_xlfn.XLOOKUP(D41,客户信息底表!BD:BD,客户信息底表!R:R,,0),"底表未登记"))))) | G41: =IF(D41="","",IFERROR(_xlfn.XLOOKUP(D41,客户信息底表!B:B,客户信息底表!L:L,,0),IFERROR(_xlfn.XLOOKUP(D41,客户信息底表!BB:BB,客户信息底表!L:L,,0),IFERROR(_xlfn.XLOOKUP(D41,客户信息底表!BC:BC,客户信息底表!L:L,,0),IFERROR(_xlfn.XLOOKUP(D41,客户信息底表!BD:BD,客户信息底表!L:L,,0),"底表未登记"))))) | H41: =IF(D41="","",IFERROR(_xlfn.XLOOKUP(D41,客户信息底表!B:B,客户信息底表!G:G,,0),IFERROR(_xlfn.XLOOKUP(D41,客户信息底表!BB:BB,客户信息底表!G:G,,0),IFERROR(_xlfn.XLOOKUP(D41,客户信息底表!BC:BC,客户信息底表!G:G,,0),IFERROR(_xlfn.XLOOKUP(D41,客户信息底表!BD:BD,客户信息底表!G:G,,0),"底表未登记"))))) | I41: =IF(D41="","","整："&数据输入表!J44&"，散："&数据输入表!K44&"；重量kg："&数据输入表!L44&"，体积："&数据输入表!M44)
A42: =IF(D42<>"",$A$2,"") | C42: =IF(D42<>"",ROW()-1,"") | E42: =IF(D42="","",IFERROR(_xlfn.XLOOKUP(D42,客户信息底表!B:B,客户信息底表!Q:Q,,0),IFERROR(_xlfn.XLOOKUP(D42,客户信息底表!BB:BB,客户信息底表!Q:Q,,0),IFERROR(_xlfn.XLOOKUP(D42,客户信息底表!BC:BC,客户信息底表!Q:Q,,0),IFERROR(_xlfn.XLOOKUP(D42,客户信息底表!BD:BD,客户信息底表!Q:Q,,0),"底表未登记"))))) | F42: =IF(D42="","",IFERROR(_xlfn.XLOOKUP(D42,客户信息底表!B:B,客户信息底表!R:R,,0),IFERROR(_xlfn.XLOOKUP(D42,客户信息底表!BB:BB,客户信息底表!R:R,,0),IFERROR(_xlfn.XLOOKUP(D42,客户信息底表!BC:BC,客户信息底表!R:R,,0),IFERROR(_xlfn.XLOOKUP(D42,客户信息底表!BD:BD,客户信息底表!R:R,,0),"底表未登记"))))) | G42: =IF(D42="","",IFERROR(_xlfn.XLOOKUP(D42,客户信息底表!B:B,客户信息底表!L:L,,0),IFERROR(_xlfn.XLOOKUP(D42,客户信息底表!BB:BB,客户信息底表!L:L,,0),IFERROR(_xlfn.XLOOKUP(D42,客户信息底表!BC:BC,客户信息底表!L:L,,0),IFERROR(_xlfn.XLOOKUP(D42,客户信息底表!BD:BD,客户信息底表!L:L,,0),"底表未登记"))))) | H42: =IF(D42="","",IFERROR(_xlfn.XLOOKUP(D42,客户信息底表!B:B,客户信息底表!G:G,,0),IFERROR(_xlfn.XLOOKUP(D42,客户信息底表!BB:BB,客户信息底表!G:G,,0),IFERROR(_xlfn.XLOOKUP(D42,客户信息底表!BC:BC,客户信息底表!G:G,,0),IFERROR(_xlfn.XLOOKUP(D42,客户信息底表!BD:BD,客户信息底表!G:G,,0),"底表未登记"))))) | I42: =IF(D42="","","整："&数据输入表!J45&"，散："&数据输入表!K45&"；重量kg："&数据输入表!L45&"，体积："&数据输入表!M45)
A43: =IF(D43<>"",$A$2,"") | C43: =IF(D43<>"",ROW()-1,"") | E43: =IF(D43="","",IFERROR(_xlfn.XLOOKUP(D43,客户信息底表!B:B,客户信息底表!Q:Q,,0),IFERROR(_xlfn.XLOOKUP(D43,客户信息底表!BB:BB,客户信息底表!Q:Q,,0),IFERROR(_xlfn.XLOOKUP(D43,客户信息底表!BC:BC,客户信息底表!Q:Q,,0),IFERROR(_xlfn.XLOOKUP(D43,客户信息底表!BD:BD,客户信息底表!Q:Q,,0),"底表未登记"))))) | G43: =IF(D43="","",IFERROR(_xlfn.XLOOKUP(D43,客户信息底表!B:B,客户信息底表!L:L,,0),IFERROR(_xlfn.XLOOKUP(D43,客户信息底表!BB:BB,客户信息底表!L:L,,0),IFERROR(_xlfn.XLOOKUP(D43,客户信息底表!BC:BC,客户信息底表!L:L,,0),IFERROR(_xlfn.XLOOKUP(D43,客户信息底表!BD:BD,客户信息底表!L:L,,0),"底表未登记"))))) | H43: =IF(D43="","",IFERROR(_xlfn.XLOOKUP(D43,客户信息底表!B:B,客户信息底表!G:G,,0),IFERROR(_xlfn.XLOOKUP(D43,客户信息底表!BB:BB,客户信息底表!G:G,,0),IFERROR(_xlfn.XLOOKUP(D43,客户信息底表!BC:BC,客户信息底表!G:G,,0),IFERROR(_xlfn.XLOOKUP(D43,客户信息底表!BD:BD,客户信息底表!G:G,,0),"底表未登记"))))) | I43: =IF(D43="","","整："&数据输入表!J46&"，散："&数据输入表!K46&"；重量kg："&数据输入表!L46&"，体积："&数据输入表!M46)
A44: =IF(D44<>"",$A$2,"") | C44: =IF(D44<>"",ROW()-1,"") | E44: =IF(D44="","",IFERROR(_xlfn.XLOOKUP(D44,客户信息底表!B:B,客户信息底表!Q:Q,,0),IFERROR(_xlfn.XLOOKUP(D44,客户信息底表!BB:BB,客户信息底表!Q:Q,,0),IFERROR(_xlfn.XLOOKUP(D44,客户信息底表!BC:BC,客户信息底表!Q:Q,,0),IFERROR(_xlfn.XLOOKUP(D44,客户信息底表!BD:BD,客户信息底表!Q:Q,,0),"底表未登记"))))) | G44: =IF(D44="","",IFERROR(_xlfn.XLOOKUP(D44,客户信息底表!B:B,客户信息底表!L:L,,0),IFERROR(_xlfn.XLOOKUP(D44,客户信息底表!BB:BB,客户信息底表!L:L,,0),IFERROR(_xlfn.XLOOKUP(D44,客户信息底表!BC:BC,客户信息底表!L:L,,0),IFERROR(_xlfn.XLOOKUP(D44,客户信息底表!BD:BD,客户信息底表!L:L,,0),"底表未登记"))))) | H44: =IF(D44="","",IFERROR(_xlfn.XLOOKUP(D44,客户信息底表!B:B,客户信息底表!G:G,,0),IFERROR(_xlfn.XLOOKUP(D44,客户信息底表!BB:BB,客户信息底表!G:G,,0),IFERROR(_xlfn.XLOOKUP(D44,客户信息底表!BC:BC,客户信息底表!G:G,,0),IFERROR(_xlfn.XLOOKUP(D44,客户信息底表!BD:BD,客户信息底表!G:G,,0),"底表未登记"))))) | I44: =IF(D44="","","整："&数据输入表!J47&"，散："&数据输入表!K47&"；重量kg："&数据输入表!L47&"，体积："&数据输入表!M47)
A45: =IF(D45<>"",$A$2,"") | C45: =IF(D45<>"",ROW()-1,"") | E45: =IF(D45="","",IFERROR(_xlfn.XLOOKUP(D45,客户信息底表!B:B,客户信息底表!Q:Q,,0),IFERROR(_xlfn.XLOOKUP(D45,客户信息底表!BB:BB,客户信息底表!Q:Q,,0),IFERROR(_xlfn.XLOOKUP(D45,客户信息底表!BC:BC,客户信息底表!Q:Q,,0),IFERROR(_xlfn.XLOOKUP(D45,客户信息底表!BD:BD,客户信息底表!Q:Q,,0),"底表未登记"))))) | G45: =IF(D45="","",IFERROR(_xlfn.XLOOKUP(D45,客户信息底表!B:B,客户信息底表!L:L,,0),IFERROR(_xlfn.XLOOKUP(D45,客户信息底表!BB:BB,客户信息底表!L:L,,0),IFERROR(_xlfn.XLOOKUP(D45,客户信息底表!BC:BC,客户信息底表!L:L,,0),IFERROR(_xlfn.XLOOKUP(D45,客户信息底表!BD:BD,客户信息底表!L:L,,0),"底表未登记"))))) | H45: =IF(D45="","",IFERROR(_xlfn.XLOOKUP(D45,客户信息底表!B:B,客户信息底表!G:G,,0),IFERROR(_xlfn.XLOOKUP(D45,客户信息底表!BB:BB,客户信息底表!G:G,,0),IFERROR(_xlfn.XLOOKUP(D45,客户信息底表!BC:BC,客户信息底表!G:G,,0),IFERROR(_xlfn.XLOOKUP(D45,客户信息底表!BD:BD,客户信息底表!G:G,,0),"底表未登记"))))) | I45: =IF(D45="","","整："&数据输入表!J48&"，散："&数据输入表!K48&"；重量kg："&数据输入表!L48&"，体积："&数据输入表!M48)
A46: =IF(D46<>"",$A$2,"") | C46: =IF(D46<>"",ROW()-1,"") | E46: =IF(D46="","",IFERROR(_xlfn.XLOOKUP(D46,客户信息底表!B:B,客户信息底表!Q:Q,,0),IFERROR(_xlfn.XLOOKUP(D46,客户信息底表!BB:BB,客户信息底表!Q:Q,,0),IFERROR(_xlfn.XLOOKUP(D46,客户信息底表!BC:BC,客户信息底表!Q:Q,,0),IFERROR(_xlfn.XLOOKUP(D46,客户信息底表!BD:BD,客户信息底表!Q:Q,,0),"底表未登记"))))) | G46: =IF(D46="","",IFERROR(_xlfn.XLOOKUP(D46,客户信息底表!B:B,客户信息底表!L:L,,0),IFERROR(_xlfn.XLOOKUP(D46,客户信息底表!BB:BB,客户信息底表!L:L,,0),IFERROR(_xlfn.XLOOKUP(D46,客户信息底表!BC:BC,客户信息底表!L:L,,0),IFERROR(_xlfn.XLOOKUP(D46,客户信息底表!BD:BD,客户信息底表!L:L,,0),"底表未登记"))))) | H46: =IF(D46="","",IFERROR(_xlfn.XLOOKUP(D46,客户信息底表!B:B,客户信息底表!G:G,,0),IFERROR(_xlfn.XLOOKUP(D46,客户信息底表!BB:BB,客户信息底表!G:G,,0),IFERROR(_xlfn.XLOOKUP(D46,客户信息底表!BC:BC,客户信息底表!G:G,,0),IFERROR(_xlfn.XLOOKUP(D46,客户信息底表!BD:BD,客户信息底表!G:G,,0),"底表未登记"))))) | I46: =IF(D46="","","整："&数据输入表!J49&"，散："&数据输入表!K49&"；重量kg："&数据输入表!L49&"，体积："&数据输入表!M49)
A47: =IF(D47<>"",$A$2,"") | C47: =IF(D47<>"",ROW()-1,"") | E47: =IF(D47="","",IFERROR(_xlfn.XLOOKUP(D47,客户信息底表!B:B,客户信息底表!Q:Q,,0),IFERROR(_xlfn.XLOOKUP(D47,客户信息底表!BB:BB,客户信息底表!Q:Q,,0),IFERROR(_xlfn.XLOOKUP(D47,客户信息底表!BC:BC,客户信息底表!Q:Q,,0),IFERROR(_xlfn.XLOOKUP(D47,客户信息底表!BD:BD,客户信息底表!Q:Q,,0),"底表未登记"))))) | G47: =IF(D47="","",IFERROR(_xlfn.XLOOKUP(D47,客户信息底表!B:B,客户信息底表!L:L,,0),IFERROR(_xlfn.XLOOKUP(D47,客户信息底表!BB:BB,客户信息底表!L:L,,0),IFERROR(_xlfn.XLOOKUP(D47,客户信息底表!BC:BC,客户信息底表!L:L,,0),IFERROR(_xlfn.XLOOKUP(D47,客户信息底表!BD:BD,客户信息底表!L:L,,0),"底表未登记"))))) | H47: =IF(D47="","",IFERROR(_xlfn.XLOOKUP(D47,客户信息底表!B:B,客户信息底表!G:G,,0),IFERROR(_xlfn.XLOOKUP(D47,客户信息底表!BB:BB,客户信息底表!G:G,,0),IFERROR(_xlfn.XLOOKUP(D47,客户信息底表!BC:BC,客户信息底表!G:G,,0),IFERROR(_xlfn.XLOOKUP(D47,客户信息底表!BD:BD,客户信息底表!G:G,,0),"底表未登记"))))) | I47: =IF(D47="","","整："&数据输入表!J50&"，散："&数据输入表!K50&"；重量kg："&数据输入表!L50&"，体积："&数据输入表!M50)
A48: =IF(D48<>"",$A$2,"") | C48: =IF(D48<>"",ROW()-1,"") | E48: =IF(D48="","",IFERROR(_xlfn.XLOOKUP(D48,客户信息底表!B:B,客户信息底表!Q:Q,,0),IFERROR(_xlfn.XLOOKUP(D48,客户信息底表!BB:BB,客户信息底表!Q:Q,,0),IFERROR(_xlfn.XLOOKUP(D48,客户信息底表!BC:BC,客户信息底表!Q:Q,,0),IFERROR(_xlfn.XLOOKUP(D48,客户信息底表!BD:BD,客户信息底表!Q:Q,,0),"底表未登记"))))) | G48: =IF(D48="","",IFERROR(_xlfn.XLOOKUP(D48,客户信息底表!B:B,客户信息底表!L:L,,0),IFERROR(_xlfn.XLOOKUP(D48,客户信息底表!BB:BB,客户信息底表!L:L,,0),IFERROR(_xlfn.XLOOKUP(D48,客户信息底表!BC:BC,客户信息底表!L:L,,0),IFERROR(_xlfn.XLOOKUP(D48,客户信息底表!BD:BD,客户信息底表!L:L,,0),"底表未登记"))))) | H48: =IF(D48="","",IFERROR(_xlfn.XLOOKUP(D48,客户信息底表!B:B,客户信息底表!G:G,,0),IFERROR(_xlfn.XLOOKUP(D48,客户信息底表!BB:BB,客户信息底表!G:G,,0),IFERROR(_xlfn.XLOOKUP(D48,客户信息底表!BC:BC,客户信息底表!G:G,,0),IFERROR(_xlfn.XLOOKUP(D48,客户信息底表!BD:BD,客户信息底表!G:G,,0),"底表未登记"))))) | I48: =IF(D48="","","整："&数据输入表!J51&"，散："&数据输入表!K51&"；重量kg："&数据输入表!L51&"，体积："&数据输入表!M51)
A49: =IF(D49<>"",$A$2,"") | C49: =IF(D49<>"",ROW()-1,"") | E49: =IF(D49="","",IFERROR(_xlfn.XLOOKUP(D49,客户信息底表!B:B,客户信息底表!Q:Q,,0),IFERROR(_xlfn.XLOOKUP(D49,客户信息底表!BB:BB,客户信息底表!Q:Q,,0),IFERROR(_xlfn.XLOOKUP(D49,客户信息底表!BC:BC,客户信息底表!Q:Q,,0),IFERROR(_xlfn.XLOOKUP(D49,客户信息底表!BD:BD,客户信息底表!Q:Q,,0),"底表未登记"))))) | G49: =IF(D49="","",IFERROR(_xlfn.XLOOKUP(D49,客户信息底表!B:B,客户信息底表!L:L,,0),IFERROR(_xlfn.XLOOKUP(D49,客户信息底表!BB:BB,客户信息底表!L:L,,0),IFERROR(_xlfn.XLOOKUP(D49,客户信息底表!BC:BC,客户信息底表!L:L,,0),IFERROR(_xlfn.XLOOKUP(D49,客户信息底表!BD:BD,客户信息底表!L:L,,0),"底表未登记"))))) | H49: =IF(D49="","",IFERROR(_xlfn.XLOOKUP(D49,客户信息底表!B:B,客户信息底表!G:G,,0),IFERROR(_xlfn.XLOOKUP(D49,客户信息底表!BB:BB,客户信息底表!G:G,,0),IFERROR(_xlfn.XLOOKUP(D49,客户信息底表!BC:BC,客户信息底表!G:G,,0),IFERROR(_xlfn.XLOOKUP(D49,客户信息底表!BD:BD,客户信息底表!G:G,,0),"底表未登记"))))) | I49: =IF(D49="","","整："&数据输入表!J52&"，散："&数据输入表!K52&"；重量kg："&数据输入表!L52&"，体积："&数据输入表!M52)
A50: =IF(D50<>"",$A$2,"") | C50: =IF(D50<>"",ROW()-1,"") | E50: =IF(D50="","",IFERROR(_xlfn.XLOOKUP(D50,客户信息底表!B:B,客户信息底表!Q:Q,,0),IFERROR(_xlfn.XLOOKUP(D50,客户信息底表!BB:BB,客户信息底表!Q:Q,,0),IFERROR(_xlfn.XLOOKUP(D50,客户信息底表!BC:BC,客户信息底表!Q:Q,,0),IFERROR(_xlfn.XLOOKUP(D50,客户信息底表!BD:BD,客户信息底表!Q:Q,,0),"底表未登记"))))) | G50: =IF(D50="","",IFERROR(_xlfn.XLOOKUP(D50,客户信息底表!B:B,客户信息底表!L:L,,0),IFERROR(_xlfn.XLOOKUP(D50,客户信息底表!BB:BB,客户信息底表!L:L,,0),IFERROR(_xlfn.XLOOKUP(D50,客户信息底表!BC:BC,客户信息底表!L:L,,0),IFERROR(_xlfn.XLOOKUP(D50,客户信息底表!BD:BD,客户信息底表!L:L,,0),"底表未登记"))))) | H50: =IF(D50="","",IFERROR(_xlfn.XLOOKUP(D50,客户信息底表!B:B,客户信息底表!G:G,,0),IFERROR(_xlfn.XLOOKUP(D50,客户信息底表!BB:BB,客户信息底表!G:G,,0),IFERROR(_xlfn.XLOOKUP(D50,客户信息底表!BC:BC,客户信息底表!G:G,,0),IFERROR(_xlfn.XLOOKUP(D50,客户信息底表!BD:BD,客户信息底表!G:G,,0),"底表未登记"))))) | I50: =IF(D50="","","整："&数据输入表!J53&"，散："&数据输入表!K53&"；重量kg："&数据输入表!L53&"，体积："&数据输入表!M53)
A51: =IF(D51<>"",$A$2,"") | C51: =IF(D51<>"",ROW()-1,"") | E51: =IF(D51="","",IFERROR(_xlfn.XLOOKUP(D51,客户信息底表!B:B,客户信息底表!Q:Q,,0),IFERROR(_xlfn.XLOOKUP(D51,客户信息底表!BB:BB,客户信息底表!Q:Q,,0),IFERROR(_xlfn.XLOOKUP(D51,客户信息底表!BC:BC,客户信息底表!Q:Q,,0),IFERROR(_xlfn.XLOOKUP(D51,客户信息底表!BD:BD,客户信息底表!Q:Q,,0),"底表未登记"))))) | G51: =IF(D51="","",IFERROR(_xlfn.XLOOKUP(D51,客户信息底表!B:B,客户信息底表!L:L,,0),IFERROR(_xlfn.XLOOKUP(D51,客户信息底表!BB:BB,客户信息底表!L:L,,0),IFERROR(_xlfn.XLOOKUP(D51,客户信息底表!BC:BC,客户信息底表!L:L,,0),IFERROR(_xlfn.XLOOKUP(D51,客户信息底表!BD:BD,客户信息底表!L:L,,0),"底表未登记"))))) | H51: =IF(D51="","",IFERROR(_xlfn.XLOOKUP(D51,客户信息底表!B:B,客户信息底表!G:G,,0),IFERROR(_xlfn.XLOOKUP(D51,客户信息底表!BB:BB,客户信息底表!G:G,,0),IFERROR(_xlfn.XLOOKUP(D51,客户信息底表!BC:BC,客户信息底表!G:G,,0),IFERROR(_xlfn.XLOOKUP(D51,客户信息底表!BD:BD,客户信息底表!G:G,,0),"底表未登记"))))) | I51: =IF(D51="","","整："&数据输入表!J54&"，散："&数据输入表!K54&"；重量kg："&数据输入表!L54&"，体积："&数据输入表!M54)
...

Sheet CustomerLine
A1: 运单号 | B1: 门店节点编号 | C1: 客户编号 | D1: 客户名称 | E1: 联系人 | F1: 联系电话 | G1: 组织 | H1: 部门名称 | I1: 业务员 | J1: 渠道 | K1: 客户等级 | L1: 是否允许货到付款 | M1: 客户状态 | N1: 内部往来单位 | O1: 发票类型 | P1: 注册电话 | Q1: 注册地址 | R1: 客户序号 | S1: 客户地址 | T1: 省 | U1: 市 | V1: 区 | W1: 经度 | X1: 纬度 | Y1: 线路偏好 | Z1: 仓库偏好 | AA1: 停靠点顺序 | AB1: 开始收货时间 | AC1: 截止收货时间 | AD1: 收货时间段 | AE1: 不收货时间段 | AF1: 违停 | AG1: 免费停车时长_分钟 | AH1: 停车费_小时 | AI1: 停车位置 | AJ1: 停车方式 | AK1: 卸货入口 | AL1: 卸货位置 | AM1: 小巷子 | AN1: 手推车 | AO1: 托盘置换 | AP1: 保温箱置换 | AQ1: 上楼层数 | AR1: 地库限高 | AS1: 周一配送 | AT1: 周二配送 | AU1: 周三配送 | AV1: 周四配送 | AW1: 周五配送 | AX1: 周六配送 | AY1: 周日配送

Sheet OrderLine
A1: 订单行编号 | B1: 运单号 | C1: 门店节点编号 | D1: 单据号 | E1: 销售订单号 | F1: 来源参考号 | G1: 第三方单据号 | H1: 单据类型 | I1: 业务类型 | J1: 单据来源 | K1: 单据日期 | L1: 审核日期 | M1: 部门名称 | N1: 渠道 | O1: 业务员 | P1: 支付状态 | Q1: 结算状态 | R1: 单据状态 | S1: 物流状态 | T1: 制单人 | U1: 审核人 | V1: 创建日期 | W1: 订单备注 | X1: 自定义字段1

Sheet GoodsLine
A1: 订单行编号 | B1: 货号 | C1: 商品名称 | D1: 规格 | E1: 条码 | F1: 品牌 | G1: 类别 | H1: 基本单位 | I1: 单据单位 | J1: 小单位 | K1: 基本数量 | L1: 单据数量 | M1: 小单位数量 | N1: 箱数 | O1: 赠品数量 | P1: 换货数量 | Q1: 单据单价 | R1: 小单位单价 | S1: 金额 | T1: 已结算金额 | U1: 未结算金额 | V1: 税额 | W1: 不含税金额 | X1: 成本金额 | Y1: 毛利 | Z1: 毛利率 | AA1: 高于标准价 | AB1: 低于标准价 | AC1: 商品单件毛重 | AD1: 商品单件体积 | AE1: 总毛重 | AF1: 总体积 | AG1: 明细备注

Sheet 数据输入表
A1: 批次号（发车单号） | B1: LC20260421000980
A2: 原始数据（输入列） | H2: 汇总表
A3: 去重列 | B3: 保留列 | C3: 汇总列 | H3: 去重列 | I3: 保留列 | J3: 汇总列
A4: 收货单位 | B4: 收货地址 | C4: 整件数 | D4: 散件数 | E4: 重量 | F4: 方数 | H4: 收货单位 | J4: 整件数 | K4: 散件数 | L4: 重量 | M4: 方数
A5: 熊猫很忙（夏园店-广东广州） （直营） | B5: 广东省广州市黄埔区夏港街道临江路3号自编 102房熊猫很忙6688 | C5: 3 | D5: 39 | E5: 2.49 | F5: 0.01 | H5: {=_xlfn.UNIQUE(_xlfn._xlws.FILTER(SUBSTITUTE(SUBSTITUTE(A5:A10003,CHAR(13),""),CHAR(10),""),SUBSTITUTE(SUBSTITUTE(A5:A10003,CHAR(13),""),CHAR(10),"")<>""))} -> 熊猫很忙（夏园店-广东广州）（直营） | I5: {=IF(H5="","",_xlfn.XLOOKUP(H5,TRIM(SUBSTITUTE(SUBSTITUTE(A5:A10001,CHAR(13),""),CHAR(10),"")),B5:B10001,"报错",0))} -> 广东省广州市黄埔区夏港街道临江路3号自编 102房熊猫很忙6688 | J5: {=IF(H5="","",SUMPRODUCT((TRIM(SUBSTITUTE(SUBSTITUTE($A$5:$A$10003,CHAR(13),""),CHAR(10),""))=H5)*--$C$5:$C$10003))} -> 3 | K5: {=IF(H5="","",SUMPRODUCT((TRIM(SUBSTITUTE(SUBSTITUTE($A$5:$A$10003,CHAR(13),""),CHAR(10),""))=H5)*--$D$5:$D$10003))} -> 39 | L5: {=IF(H5="","",SUMPRODUCT((TRIM(SUBSTITUTE(SUBSTITUTE($A$5:$A$10003,CHAR(13),""),CHAR(10),""))=H5)*IFERROR(--$D$5:$D$10003,0)))} -> 39 | M5: {=IF(H5="","",SUMPRODUCT((TRIM(SUBSTITUTE(SUBSTITUTE($A$5:$A$10003,CHAR(13),""),CHAR(10),""))=H5)*IFERROR(--$F$5:$F$10003,0)))} -> 0.01
A6: 鲸选超市（广州板桥店) | B6: 广东省广州市番禺区南村镇南村镇兴南大道 902号板桥商务大厦3楼315号 | C6: 11 | D6: 190 | E6: 14.85 | F6: 0.03 | H6: 鲸选超市（广州板桥店) | I6: {=IF(H6="","",_xlfn.XLOOKUP(H6,TRIM(SUBSTITUTE(SUBSTITUTE(A6:A10002,CHAR(13),""),CHAR(10),"")),B6:B10002,"报错",0))} -> 广东省广州市番禺区南村镇南村镇兴南大道 902号板桥商务大厦3楼315号 | J6: {=IF(H6="","",SUMPRODUCT((TRIM(SUBSTITUTE(SUBSTITUTE($A$5:$A$10003,CHAR(13),""),CHAR(10),""))=H6)*--$C$5:$C$10003))} -> 11 | K6: {=IF(H6="","",SUMPRODUCT((TRIM(SUBSTITUTE(SUBSTITUTE($A$5:$A$10003,CHAR(13),""),CHAR(10),""))=H6)*--$D$5:$D$10003))} -> 190 | L6: {=IF(H6="","",SUMPRODUCT((TRIM(SUBSTITUTE(SUBSTITUTE($A$5:$A$10003,CHAR(13),""),CHAR(10),""))=H6)*IFERROR(--$D$5:$D$10003,0)))} -> 190 | M6: {=IF(H6="","",SUMPRODUCT((TRIM(SUBSTITUTE(SUBSTITUTE($A$5:$A$10003,CHAR(13),""),CHAR(10),""))=H6)*IFERROR(--$F$5:$F$10003,0)))} -> 0.03
A7: 鲸选超市（广州番禺店) | B7: 广东省广州市番禺区南村镇南村镇敏捷上城国 际【2期2座112店铺2楼京东便利店仓库】 | C7: 4 | D7: 110 | E7: 8.28 | F7: 0.01 | H7: 鲸选超市（广州番禺店) | I7: {=IF(H7="","",_xlfn.XLOOKUP(H7,TRIM(SUBSTITUTE(SUBSTITUTE(A7:A10003,CHAR(13),""),CHAR(10),"")),B7:B10003,"报错",0))} -> 广东省广州市番禺区南村镇南村镇敏捷上城国 际【2期2座112店铺2楼京东便利店仓库】 | J7: {=IF(H7="","",SUMPRODUCT((TRIM(SUBSTITUTE(SUBSTITUTE($A$5:$A$10003,CHAR(13),""),CHAR(10),""))=H7)*--$C$5:$C$10003))} -> 4 | K7: {=IF(H7="","",SUMPRODUCT((TRIM(SUBSTITUTE(SUBSTITUTE($A$5:$A$10003,CHAR(13),""),CHAR(10),""))=H7)*--$D$5:$D$10003))} -> 110 | L7: {=IF(H7="","",SUMPRODUCT((TRIM(SUBSTITUTE(SUBSTITUTE($A$5:$A$10003,CHAR(13),""),CHAR(10),""))=H7)*IFERROR(--$D$5:$D$10003,0)))} -> 110 | M7: {=IF(H7="","",SUMPRODUCT((TRIM(SUBSTITUTE(SUBSTITUTE($A$5:$A$10003,CHAR(13),""),CHAR(10),""))=H7)*IFERROR(--$F$5:$F$10003,0)))} -> 0.01
A8: 时光里便利超市（广州番禺万博店） | B8: 广东省广州市番禺区南村镇南村镇登云大路 2号之六105房 | C8: 6 | D8: 107 | E8: 20.02 | F8: 0.05 | H8: 时光里便利超市（广州番禺万博店） | I8: {=IF(H8="","",_xlfn.XLOOKUP(H8,TRIM(SUBSTITUTE(SUBSTITUTE(A8:A10004,CHAR(13),""),CHAR(10),"")),B8:B10004,"报错",0))} -> 广东省广州市番禺区南村镇南村镇登云大路 2号之六105房 | J8: {=IF(H8="","",SUMPRODUCT((TRIM(SUBSTITUTE(SUBSTITUTE($A$5:$A$10003,CHAR(13),""),CHAR(10),""))=H8)*--$C$5:$C$10003))} -> 6 | K8: {=IF(H8="","",SUMPRODUCT((TRIM(SUBSTITUTE(SUBSTITUTE($A$5:$A$10003,CHAR(13),""),CHAR(10),""))=H8)*--$D$5:$D$10003))} -> 107 | L8: {=IF(H8="","",SUMPRODUCT((TRIM(SUBSTITUTE(SUBSTITUTE($A$5:$A$10003,CHAR(13),""),CHAR(10),""))=H8)*IFERROR(--$D$5:$D$10003,0)))} -> 107 | M8: {=IF(H8="","",SUMPRODUCT((TRIM(SUBSTITUTE(SUBSTITUTE($A$5:$A$10003,CHAR(13),""),CHAR(10),""))=H8)*IFERROR(--$F$5:$F$10003,0)))} -> 0.05
A9: 熊猫很忙（大石店-广东广州） | B9: 广东省广州市番禺区大石街道大石街大山村富 山路四街1号胜文工业园2栋1楼103室 | C9: 2 | D9: 125 | E9: 4.57 | F9: 0.01 | H9: 熊猫很忙（大石店-广东广州） | I9: {=IF(H9="","",_xlfn.XLOOKUP(H9,TRIM(SUBSTITUTE(SUBSTITUTE(A9:A10005,CHAR(13),""),CHAR(10),"")),B9:B10005,"报错",0))} -> 广东省广州市番禺区大石街道大石街大山村富 山路四街1号胜文工业园2栋1楼103室 | J9: {=IF(H9="","",SUMPRODUCT((TRIM(SUBSTITUTE(SUBSTITUTE($A$5:$A$10003,CHAR(13),""),CHAR(10),""))=H9)*--$C$5:$C$10003))} -> 2 | K9: {=IF(H9="","",SUMPRODUCT((TRIM(SUBSTITUTE(SUBSTITUTE($A$5:$A$10003,CHAR(13),""),CHAR(10),""))=H9)*--$D$5:$D$10003))} -> 125 | L9: {=IF(H9="","",SUMPRODUCT((TRIM(SUBSTITUTE(SUBSTITUTE($A$5:$A$10003,CHAR(13),""),CHAR(10),""))=H9)*IFERROR(--$D$5:$D$10003,0)))} -> 125 | M9: {=IF(H9="","",SUMPRODUCT((TRIM(SUBSTITUTE(SUBSTITUTE($A$5:$A$10003,CHAR(13),""),CHAR(10),""))=H9)*IFERROR(--$F$5:$F$10003,0)))} -> 0.01
A10: 值小团（广州大石店） | B10: 广东省广州市番禺区大石街道大石街道大石镇 朝阳东路170号201房值小团超市（原玲丰服饰 ) | C10: 3 | D10: 60 | E10: 5.18 | F10: 0.01 | H10: 值小团（广州大石店） | I10: {=IF(H10="","",_xlfn.XLOOKUP(H10,TRIM(SUBSTITUTE(SUBSTITUTE(A10:A10006,CHAR(13),""),CHAR(10),"")),B10:B10006,"报错",0))} -> 广东省广州市番禺区大石街道大石街道大石镇 朝阳东路170号201房值小团超市（原玲丰服饰 ) | J10: {=IF(H10="","",SUMPRODUCT((TRIM(SUBSTITUTE(SUBSTITUTE($A$5:$A$10003,CHAR(13),""),CHAR(10),""))=H10)*--$C$5:$C$10003))} -> 3 | K10: {=IF(H10="","",SUMPRODUCT((TRIM(SUBSTITUTE(SUBSTITUTE($A$5:$A$10003,CHAR(13),""),CHAR(10),""))=H10)*--$D$5:$D$10003))} -> 60 | L10: {=IF(H10="","",SUMPRODUCT((TRIM(SUBSTITUTE(SUBSTITUTE($A$5:$A$10003,CHAR(13),""),CHAR(10),""))=H10)*IFERROR(--$D$5:$D$10003,0)))} -> 60 | M10: {=IF(H10="","",SUMPRODUCT((TRIM(SUBSTITUTE(SUBSTITUTE($A$5:$A$10003,CHAR(13),""),CHAR(10),""))=H10)*IFERROR(--$F$5:$F$10003,0)))} -> 0.01
A11: 鲸选超市（广州大石店) | B11: 广东省广州市番禺区大石街道大石街道大涌路 157号大石伟讯电子数码城4楼421铺 | C11: 9 | D11: 207 | E11: 15.23 | F11: 0.03 | H11: 鲸选超市（广州大石店) | I11: {=IF(H11="","",_xlfn.XLOOKUP(H11,TRIM(SUBSTITUTE(SUBSTITUTE(A11:A10007,CHAR(13),""),CHAR(10),"")),B11:B10007,"报错",0))} -> 广东省广州市番禺区大石街道大石街道大涌路 157号大石伟讯电子数码城4楼421铺 | J11: {=IF(H11="","",SUMPRODUCT((TRIM(SUBSTITUTE(SUBSTITUTE($A$5:$A$10003,CHAR(13),""),CHAR(10),""))=H11)*--$C$5:$C$10003))} -> 9 | K11: {=IF(H11="","",SUMPRODUCT((TRIM(SUBSTITUTE(SUBSTITUTE($A$5:$A$10003,CHAR(13),""),CHAR(10),""))=H11)*--$D$5:$D$10003))} -> 207 | L11: {=IF(H11="","",SUMPRODUCT((TRIM(SUBSTITUTE(SUBSTITUTE($A$5:$A$10003,CHAR(13),""),CHAR(10),""))=H11)*IFERROR(--$D$5:$D$10003,0)))} -> 207 | M11: {=IF(H11="","",SUMPRODUCT((TRIM(SUBSTITUTE(SUBSTITUTE($A$5:$A$10003,CHAR(13),""),CHAR(10),""))=H11)*IFERROR(--$F$5:$F$10003,0)))} -> 0.03
A12: 熊猫很忙（鹤洞店-广东广州）（直营） | B12: 广东省广州市荔湾区白鹤洞街道鹤洞路346号 218室2楼送货上门6688不放驿站 | C12: 6 | D12: 102 | E12: 6.15 | F12: 0.01 | H12: 熊猫很忙（鹤洞店-广东广州）（直营） | I12: {=IF(H12="","",_xlfn.XLOOKUP(H12,TRIM(SUBSTITUTE(SUBSTITUTE(A12:A10008,CHAR(13),""),CHAR(10),"")),B12:B10008,"报错",0))} -> 广东省广州市荔湾区白鹤洞街道鹤洞路346号 218室2楼送货上门6688不放驿站 | J12: {=IF(H12="","",SUMPRODUCT((TRIM(SUBSTITUTE(SUBSTITUTE($A$5:$A$10003,CHAR(13),""),CHAR(10),""))=H12)*--$C$5:$C$10003))} -> 6 | K12: {=IF(H12="","",SUMPRODUCT((TRIM(SUBSTITUTE(SUBSTITUTE($A$5:$A$10003,CHAR(13),""),CHAR(10),""))=H12)*--$D$5:$D$10003))} -> 102 | L12: {=IF(H12="","",SUMPRODUCT((TRIM(SUBSTITUTE(SUBSTITUTE($A$5:$A$10003,CHAR(13),""),CHAR(10),""))=H12)*IFERROR(--$D$5:$D$10003,0)))} -> 102 | M12: {=IF(H12="","",SUMPRODUCT((TRIM(SUBSTITUTE(SUBSTITUTE($A$5:$A$10003,CHAR(13),""),CHAR(10),""))=H12)*IFERROR(--$F$5:$F$10003,0)))} -> 0.01
A13: 值小团（广州芳村店） | B13: 广东省广州市荔湾区白鹤洞街道坑口大街 138 号红岗工业区1 号首层 101、102 室 | C13: 7 | D13: 114 | E13: 12.6 | F13: 0.03 | H13: 值小团（广州芳村店） | I13: {=IF(H13="","",_xlfn.XLOOKUP(H13,TRIM(SUBSTITUTE(SUBSTITUTE(A13:A10009,CHAR(13),""),CHAR(10),"")),B13:B10009,"报错",0))} -> 广东省广州市荔湾区白鹤洞街道坑口大街 138 号红岗工业区1 号首层 101、102 室 | J13: {=IF(H13="","",SUMPRODUCT((TRIM(SUBSTITUTE(SUBSTITUTE($A$5:$A$10003,CHAR(13),""),CHAR(10),""))=H13)*--$C$5:$C$10003))} -> 7 | K13: {=IF(H13="","",SUMPRODUCT((TRIM(SUBSTITUTE(SUBSTITUTE($A$5:$A$10003,CHAR(13),""),CHAR(10),""))=H13)*--$D$5:$D$10003))} -> 114 | L13: {=IF(H13="","",SUMPRODUCT((TRIM(SUBSTITUTE(SUBSTITUTE($A$5:$A$10003,CHAR(13),""),CHAR(10),""))=H13)*IFERROR(--$D$5:$D$10003,0)))} -> 114 | M13: {=IF(H13="","",SUMPRODUCT((TRIM(SUBSTITUTE(SUBSTITUTE($A$5:$A$10003,CHAR(13),""),CHAR(10),""))=H13)*IFERROR(--$F$5:$F$10003,0)))} -> 0.03
A14: 鲸选超市（广州芳村店) | B14: 广东省广州市荔湾区冲口街道花溪路3号 坑口 工业区1栋2楼215鲸选超市里面(有电梯) | C14: 6 | D14: 162 | E14: 11.57 | F14: 0.02 | H14: 鲸选超市（广州芳村店) | I14: {=IF(H14="","",_xlfn.XLOOKUP(H14,TRIM(SUBSTITUTE(SUBSTITUTE(A14:A10010,CHAR(13),""),CHAR(10),"")),B14:B10010,"报错",0))} -> 广东省广州市荔湾区冲口街道花溪路3号 坑口 工业区1栋2楼215鲸选超市里面(有电梯) | J14: {=IF(H14="","",SUMPRODUCT((TRIM(SUBSTITUTE(SUBSTITUTE($A$5:$A$10003,CHAR(13),""),CHAR(10),""))=H14)*--$C$5:$C$10003))} -> 6 | K14: {=IF(H14="","",SUMPRODUCT((TRIM(SUBSTITUTE(SUBSTITUTE($A$5:$A$10003,CHAR(13),""),CHAR(10),""))=H14)*--$D$5:$D$10003))} -> 162 | L14: {=IF(H14="","",SUMPRODUCT((TRIM(SUBSTITUTE(SUBSTITUTE($A$5:$A$10003,CHAR(13),""),CHAR(10),""))=H14)*IFERROR(--$D$5:$D$10003,0)))} -> 162 | M14: {=IF(H14="","",SUMPRODUCT((TRIM(SUBSTITUTE(SUBSTITUTE($A$5:$A$10003,CHAR(13),""),CHAR(10),""))=H14)*IFERROR(--$F$5:$F$10003,0)))} -> 0.02
A15: 畅盈到家超市（广州海珠店） | B15: 广东省广州市海珠区南石头街道南石头街道工 业大道中路385号大院11号楼224房 | C15: 8 | D15: 56 | E15: 50.61 | F15: 0.1 | H15: 畅盈到家超市（广州海珠店） | I15: {=IF(H15="","",_xlfn.XLOOKUP(H15,TRIM(SUBSTITUTE(SUBSTITUTE(A15:A10011,CHAR(13),""),CHAR(10),"")),B15:B10011,"报错",0))} -> 广东省广州市海珠区南石头街道南石头街道工 业大道中路385号大院11号楼224房 | J15: {=IF(H15="","",SUMPRODUCT((TRIM(SUBSTITUTE(SUBSTITUTE($A$5:$A$10003,CHAR(13),""),CHAR(10),""))=H15)*--$C$5:$C$10003))} -> 9 | K15: {=IF(H15="","",SUMPRODUCT((TRIM(SUBSTITUTE(SUBSTITUTE($A$5:$A$10003,CHAR(13),""),CHAR(10),""))=H15)*--$D$5:$D$10003))} -> 178 | L15: {=IF(H15="","",SUMPRODUCT((TRIM(SUBSTITUTE(SUBSTITUTE($A$5:$A$10003,CHAR(13),""),CHAR(10),""))=H15)*IFERROR(--$D$5:$D$10003,0)))} -> 178 | M15: {=IF(H15="","",SUMPRODUCT((TRIM(SUBSTITUTE(SUBSTITUTE($A$5:$A$10003,CHAR(13),""),CHAR(10),""))=H15)*IFERROR(--$F$5:$F$10003,0)))} -> 0.12
A16: 畅盈到家超市（广州海珠店） | B16: 广东省广州市海珠区南石头街道南石头街道工 业大道中路385号大院11号楼224房 | C16: 1 | D16: 122 | E16: 8.26 | F16: 0.02 | H16: 值小团（广州海珠店） | I16: {=IF(H16="","",_xlfn.XLOOKUP(H16,TRIM(SUBSTITUTE(SUBSTITUTE(A16:A10012,CHAR(13),""),CHAR(10),"")),B16:B10012,"报错",0))} -> 广东省广州市海珠区昌岗街道信雅路54 | J16: {=IF(H16="","",SUMPRODUCT((TRIM(SUBSTITUTE(SUBSTITUTE($A$5:$A$10003,CHAR(13),""),CHAR(10),""))=H16)*--$C$5:$C$10003))} -> 12 | K16: {=IF(H16="","",SUMPRODUCT((TRIM(SUBSTITUTE(SUBSTITUTE($A$5:$A$10003,CHAR(13),""),CHAR(10),""))=H16)*--$D$5:$D$10003))} -> 135 | L16: {=IF(H16="","",SUMPRODUCT((TRIM(SUBSTITUTE(SUBSTITUTE($A$5:$A$10003,CHAR(13),""),CHAR(10),""))=H16)*IFERROR(--$D$5:$D$10003,0)))} -> 135 | M16: {=IF(H16="","",SUMPRODUCT((TRIM(SUBSTITUTE(SUBSTITUTE($A$5:$A$10003,CHAR(13),""),CHAR(10),""))=H16)*IFERROR(--$F$5:$F$10003,0)))} -> 0.17
A17: 值小团（广州海珠店） | B17: 广东省广州市海珠区昌岗街道信雅路54 | C17: 7 | D17: 15 | E17: 31.75 | F17: 0.15 | I17: {=IF(H17="","",_xlfn.XLOOKUP(H17,TRIM(SUBSTITUTE(SUBSTITUTE(A17:A10013,CHAR(13),""),CHAR(10),"")),B17:B10013,"报错",0))} | J17: {=IF(H17="","",SUMPRODUCT((TRIM(SUBSTITUTE(SUBSTITUTE($A$5:$A$10003,CHAR(13),""),CHAR(10),""))=H17)*--$C$5:$C$10003))} | K17: {=IF(H17="","",SUMPRODUCT((TRIM(SUBSTITUTE(SUBSTITUTE($A$5:$A$10003,CHAR(13),""),CHAR(10),""))=H17)*--$D$5:$D$10003))} | L17: {=IF(H17="","",SUMPRODUCT((TRIM(SUBSTITUTE(SUBSTITUTE($A$5:$A$10003,CHAR(13),""),CHAR(10),""))=H17)*IFERROR(--$D$5:$D$10003,0)))} | M17: {=IF(H17="","",SUMPRODUCT((TRIM(SUBSTITUTE(SUBSTITUTE($A$5:$A$10003,CHAR(13),""),CHAR(10),""))=H17)*IFERROR(--$F$5:$F$10003,0)))}
A18: 值小团（广州海珠店） | B18: 广东省广州市海珠区昌岗街道信雅路54 | C18: 5 | D18: 120 | E18: 9.85 | F18: 0.02 | I18: {=IF(H18="","",_xlfn.XLOOKUP(H18,TRIM(SUBSTITUTE(SUBSTITUTE(A18:A10014,CHAR(13),""),CHAR(10),"")),B18:B10014,"报错",0))} | J18: {=IF(H18="","",SUMPRODUCT((TRIM(SUBSTITUTE(SUBSTITUTE($A$5:$A$10003,CHAR(13),""),CHAR(10),""))=H18)*--$C$5:$C$10003))} | K18: {=IF(H18="","",SUMPRODUCT((TRIM(SUBSTITUTE(SUBSTITUTE($A$5:$A$10003,CHAR(13),""),CHAR(10),""))=H18)*--$D$5:$D$10003))} | L18: {=IF(H18="","",SUMPRODUCT((TRIM(SUBSTITUTE(SUBSTITUTE($A$5:$A$10003,CHAR(13),""),CHAR(10),""))=H18)*IFERROR(--$D$5:$D$10003,0)))} | M18: {=IF(H18="","",SUMPRODUCT((TRIM(SUBSTITUTE(SUBSTITUTE($A$5:$A$10003,CHAR(13),""),CHAR(10),""))=H18)*IFERROR(--$F$5:$F$10003,0)))}
I19: {=IF(H19="","",_xlfn.XLOOKUP(H19,TRIM(SUBSTITUTE(SUBSTITUTE(A19:A10015,CHAR(13),""),CHAR(10),"")),B19:B10015,"报错",0))} | J19: {=IF(H19="","",SUMPRODUCT((TRIM(SUBSTITUTE(SUBSTITUTE($A$5:$A$10003,CHAR(13),""),CHAR(10),""))=H19)*--$C$5:$C$10003))} | K19: {=IF(H19="","",SUMPRODUCT((TRIM(SUBSTITUTE(SUBSTITUTE($A$5:$A$10003,CHAR(13),""),CHAR(10),""))=H19)*--$D$5:$D$10003))} | L19: {=IF(H19="","",SUMPRODUCT((TRIM(SUBSTITUTE(SUBSTITUTE($A$5:$A$10003,CHAR(13),""),CHAR(10),""))=H19)*IFERROR(--$D$5:$D$10003,0)))} | M19: {=IF(H19="","",SUMPRODUCT((TRIM(SUBSTITUTE(SUBSTITUTE($A$5:$A$10003,CHAR(13),""),CHAR(10),""))=H19)*IFERROR(--$F$5:$F$10003,0)))}
I20: {=IF(H20="","",_xlfn.XLOOKUP(H20,TRIM(SUBSTITUTE(SUBSTITUTE(A20:A10016,CHAR(13),""),CHAR(10),"")),B20:B10016,"报错",0))} | J20: {=IF(H20="","",SUMPRODUCT((TRIM(SUBSTITUTE(SUBSTITUTE($A$5:$A$10003,CHAR(13),""),CHAR(10),""))=H20)*--$C$5:$C$10003))} | K20: {=IF(H20="","",SUMPRODUCT((TRIM(SUBSTITUTE(SUBSTITUTE($A$5:$A$10003,CHAR(13),""),CHAR(10),""))=H20)*--$D$5:$D$10003))} | L20: {=IF(H20="","",SUMPRODUCT((TRIM(SUBSTITUTE(SUBSTITUTE($A$5:$A$10003,CHAR(13),""),CHAR(10),""))=H20)*IFERROR(--$D$5:$D$10003,0)))} | M20: {=IF(H20="","",SUMPRODUCT((TRIM(SUBSTITUTE(SUBSTITUTE($A$5:$A$10003,CHAR(13),""),CHAR(10),""))=H20)*IFERROR(--$F$5:$F$10003,0)))}
